<sdf version='1.7'>
  <world name='default'>
    <plugin name='gazebo_ros_state' filename='libgazebo_ros_state.so'>
      <ros>
        <namespace>/state</namespace>
        <argument>model_states:=model_states</argument>
        <argument>link_states:=link_states</argument>
      </ros>
      <update_rate>1.0</update_rate>
    </plugin>
    <light name='sun' type='directional'>
      <cast_shadows>1</cast_shadows>
      <pose>0 0 10 0 -0 0</pose>
      <diffuse>1 1 1 1</diffuse>
      <specular>0.2 0.2 0.2 1</specular>
      <attenuation>
        <range>1000</range>
        <constant>0</constant>
        <linear>0</linear>
        <quadratic>0</quadratic>
      </attenuation>
      <direction>-0.5 0.1 -0.9</direction>
      <spot>
        <inner_angle>0</inner_angle>
        <outer_angle>0</outer_angle>
        <falloff>0</falloff>
      </spot>
    </light>
    <model name='ground_plane'>
      <static>1</static>
      <link name='link'>
        <collision name='collision'>
          <geometry>
            <plane>
              <normal>0 0 1</normal>
              <size>100 100</size>
            </plane>
          </geometry>
          <surface>
            <contact>
              <collide_bitmask>65535</collide_bitmask>
              <ode/>
            </contact>
            <friction>
              <ode>
                <mu>100</mu>
                <mu2>50</mu2>
              </ode>
              <torsional>
                <ode/>
              </torsional>
            </friction>
            <bounce/>
          </surface>
          <max_contacts>10</max_contacts>
        </collision>
        <visual name='visual'>
          <cast_shadows>0</cast_shadows>
          <geometry>
            <plane>
              <normal>0 0 1</normal>
              <size>100 100</size>
            </plane>
          </geometry>
          <material>
            <script>
              <uri>file://media/materials/scripts/gazebo.material</uri>
              <name>Gazebo/Grey</name>
            </script>
          </material>
        </visual>
        <self_collide>0</self_collide>
        <enable_wind>0</enable_wind>
        <kinematic>0</kinematic>
      </link>
    </model>
    <gravity>0 0 -9.8</gravity>
    <magnetic_field>6e-06 2.3e-05 -4.2e-05</magnetic_field>
    <atmosphere type='adiabatic'/>
    <physics type='ode'>
      <max_step_size>0.001</max_step_size>
      <real_time_factor>1</real_time_factor>
      <real_time_update_rate>1000</real_time_update_rate>
    </physics>
    <scene>
      <ambient>0.4 0.4 0.4 1</ambient>
      <background>0.7 0.7 0.7 1</background>
      <shadows>1</shadows>
    </scene>
    <audio>
      <device>default</device>
    </audio>
    <wind/>
    <spherical_coordinates>
      <surface_model>EARTH_WGS84</surface_model>
      <latitude_deg>0</latitude_deg>
      <longitude_deg>0</longitude_deg>
      <elevation>0</elevation>
      <heading_deg>0</heading_deg>
    </spherical_coordinates>
    <state world_name='default'>
      <sim_time>14430 996000000</sim_time>
      <real_time>14985 418352139</real_time>
      <wall_time>1738257633 70970980</wall_time>
      <iterations>14335154</iterations>
      <model name='aws_robomaker_warehouse_GroundB_01_0'>
        <pose>0.748933 -0.442162 0 0 -0 0</pose>
        <scale>1 1 1</scale>
        <link name='link'>
          <pose>0.748933 -0.442162 0 0 -0 0</pose>
          <velocity>0 0 0 0 -0 0</velocity>
          <acceleration>0 0 0 0 -0 0</acceleration>
          <wrench>0 0 0 0 -0 0</wrench>
        </link>
      </model>
      <model name='camera'>
        <pose>0.330308 3.90171 0.691869 3.14159 -0 1.62146</pose>
        <scale>1 1 1</scale>
        <link name='link'>
          <pose>0.330308 3.90171 0.691869 3.14159 -0 1.62146</pose>
          <velocity>-0 -0 3e-06 -0 -0 -0</velocity>
          <acceleration>0 -3e-06 -0 0 -0 0</acceleration>
          <wrench>0 -0 -0 0 -0 0</wrench>
        </link>
      </model>
      <model name='ground_plane'>
        <pose>0 0 0 0 -0 0</pose>
        <scale>1 1 1</scale>
        <link name='link'>
          <pose>0 0 0 0 -0 0</pose>
          <velocity>0 0 0 0 -0 0</velocity>
          <acceleration>0 0 0 0 -0 0</acceleration>
          <wrench>0 0 0 0 -0 0</wrench>
        </link>
      </model>
      <model name='left_robot'>
        <pose>-1.24313 0.003166 0.123316 0 0 -0.002752</pose>
        <scale>1 1 1</scale>
        <link name='left_summit_back_left_wheel_link'>
          <pose>-1.46507 0.208278 0.250316 3.14158 1.53538 3.13883</pose>
          <velocity>-0 -0 3e-06 0 -0 0</velocity>
          <acceleration>-2e-06 0 0 0 -2e-05 0</acceleration>
          <wrench>-1.6e-05 0 0 0 -0 0</wrench>
        </link>
        <link name='left_summit_back_right_wheel_link'>
          <pose>-1.46619 -0.200721 0.250316 3.14159 1.45521 3.13884</pose>
          <velocity>-0 -0 3e-06 0 -1e-06 0</velocity>
          <acceleration>-2e-06 0 -0 0 -2e-05 0</acceleration>
          <wrench>-1.6e-05 0 -0 0 -0 0</wrench>
        </link>
        <link name='left_summit_base_footprint'>
          <pose>-1.24313 0.003166 0.123316 0 0 -0.002752</pose>
          <velocity>-0 -0 3e-06 0 -0 0</velocity>
          <acceleration>-2e-06 0 -0 0 -0 0</acceleration>
          <wrench>-0.000328 1e-06 -0 0 -0 0</wrench>
        </link>
        <link name='left_summit_front_left_wheel_link'>
          <pose>-1.02007 0.207053 0.250316 3.14158 1.53536 3.13883</pose>
          <velocity>-0 -0 3e-06 1e-06 -0 0</velocity>
          <acceleration>-2e-06 0 0 0 -2e-05 0</acceleration>
          <wrench>-1.6e-05 0 0 0 -0 0</wrench>
        </link>
        <link name='left_summit_front_right_wheel_link'>
          <pose>-1.02119 -0.201946 0.250316 3.14159 1.25526 3.13884</pose>
          <velocity>-0 -0 3e-06 1e-06 -1e-06 0</velocity>
          <acceleration>-2e-06 0 -0 0 -2e-05 0</acceleration>
          <wrench>-1.6e-05 0 -0 0 -0 0</wrench>
        </link>
        <link name='ur_left_forearm_link'>
          <pose>-1.40339 -0.030082 1.22104 -1.5708 -0.110693 -2.93704</pose>
          <velocity>0 -0 3e-06 0 -0 0</velocity>
          <acceleration>1.5e-05 -0.00014 9e-06 7.7e-05 -1.8e-05 0.000161</acceleration>
          <wrench>4.3e-05 -0.000398 2.7e-05 0 -0 0</wrench>
        </link>
        <link name='ur_left_shoulder_link'>
          <pose>-1.24313 0.003166 0.828816 0 -0 0.204556</pose>
          <velocity>-0 -0 3e-06 0 -0 0</velocity>
          <acceleration>-3e-06 2e-06 1e-06 -0.00012 -2.5e-05 0.00026</acceleration>
          <wrench>-1.1e-05 8e-06 5e-06 0 -0 0</wrench>
        </link>
        <link name='ur_left_upper_arm_link'>
          <pose>-1.24313 0.003166 0.828816 1.57081 1.17548 0.204565</pose>
          <velocity>-0 -0 3e-06 0 -0 0</velocity>
          <acceleration>3.6e-05 -7.5e-05 -4.5e-05 -0.000638 -5.7e-05 0.001897</acceleration>
          <wrench>0.000291 -0.000604 -0.000365 0 -0 0</wrench>
        </link>
        <link name='ur_left_wrist_1_link'>
          <pose>-0.994635 -0.081422 1.17771 -1.57081 -1.23595 -2.93703</pose>
          <velocity>0 -0 3e-06 0 -0 0</velocity>
          <acceleration>3e-05 -0.000105 -1e-05 0.000288 3e-06 0.000131</acceleration>
          <wrench>4e-05 -0.000144 -1.3e-05 0 -0 0</wrench>
        </link>
        <link name='ur_left_wrist_2_link'>
          <pose>-0.902436 -0.062294 1.21048 -1.22823 0.208577 -1.29252</pose>
          <velocity>0 -0 3e-06 1e-06 -0 0</velocity>
          <acceleration>2.7e-05 -0.000112 -6e-06 0.00071 0.000104 0.000163</acceleration>
          <wrench>3.5e-05 -0.000145 -8e-06 0 -0 0</wrench>
        </link>
        <link name='ur_left_wrist_3_link'>
          <pose>-0.875602 -0.034426 1.1187 -2.74628 -0.055013 -0.635453</pose>
          <velocity>-0 -0 3e-06 1e-06 -0 0</velocity>
          <acceleration>2e-05 -4.9e-05 -0 0.00053 -8e-06 0.000235</acceleration>
          <wrench>1.6e-05 -3.8e-05 -0 0 -0 0</wrench>
        </link>
      </model>
      <model name='muraUse1'>
        <pose>-0.234471 6.1658 1.1243 0.000111 -3e-06 0.003074</pose>
        <scale>1 1 1</scale>
        <link name='link_0'>
          <pose>-0.234471 6.1658 1.1243 3e-06 0.000111 -1.56768</pose>
          <velocity>0 0 0 0 -0 0</velocity>
          <acceleration>-0.015329 0.001051 -9.91985 0 -0 0</acceleration>
          <wrench>-1.53287 0.105057 -991.985 0 -0 0</wrench>
        </link>
      </model>
      <model name='pacco'>
        <pose>-0.240072 5.20429 0.984314 0.000128 -6.8e-05 -0.016547</pose>
        <scale>1 1 1</scale>
        <link name='link_1'>
          <pose>-0.240072 5.20429 0.984314 0.000128 -6.8e-05 -0.016547</pose>
          <velocity>0 0 0 0 -0 0</velocity>
          <acceleration>0 0 -9.8 0 -0 0</acceleration>
          <wrench>0 0 -9.8 0 -0 0</wrench>
        </link>
      </model>
      <model name='pacco_clone'>
        <pose>-0.225605 5.55162 0.984303 3.2e-05 1.8e-05 -0.021104</pose>
        <scale>1 1 1</scale>
        <link name='link_1'>
          <pose>-0.225605 5.55162 0.984303 3.2e-05 1.8e-05 -0.021104</pose>
          <velocity>0 0 0 0 -0 0</velocity>
          <acceleration>0 0 -9.8 0 -0 0</acceleration>
          <wrench>0 0 -9.8 0 -0 0</wrench>
        </link>
      </model>
      <model name='pacco_clone_0'>
        <pose>-0.23117 5.89938 0.98432 2.5e-05 -1.1e-05 -0.022821</pose>
        <scale>1 1 1</scale>
        <link name='link_1'>
          <pose>-0.23117 5.89938 0.98432 2.5e-05 -1.1e-05 -0.022821</pose>
          <velocity>0 0 0 0 -0 0</velocity>
          <acceleration>0.516029 0.998534 -1.38588 -1.42622 -1.43428 -2.71642</acceleration>
          <wrench>0.516029 0.998534 -1.38588 0 -0 0</wrench>
        </link>
      </model>
      <model name='pacco_clone_1'>
        <pose>-0.240525 4.84347 0.984157 0.000129 -8.5e-05 -0.015898</pose>
        <scale>1 1 1</scale>
        <link name='link_1'>
          <pose>-0.240525 4.84347 0.984157 0.000129 -8.5e-05 -0.015898</pose>
          <velocity>0 0 0 0 -0 0</velocity>
          <acceleration>0 0 -9.8 0 -0 0</acceleration>
          <wrench>0 0 -9.8 0 -0 0</wrench>
        </link>
      </model>
      <model name='pacco_clone_2'>
        <pose>-3.75345 4.20072 0.343778 0.003108 -0.002032 0.000258</pose>
        <scale>1 1 1</scale>
        <link name='link_1'>
          <pose>-3.75345 4.20072 0.343778 0.003108 -0.002032 0.000258</pose>
          <velocity>0 0 0 0 -0 0</velocity>
          <acceleration>0 0 -9.8 0 -0 0</acceleration>
          <wrench>0 0 -9.8 0 -0 0</wrench>
        </link>
      </model>
      <model name='pallet2'>
        <pose>-3.62119 4.40316 0.099704 0.003105 -0.002028 -0.000169</pose>
        <scale>1 1 1</scale>
        <link name='pallet_base'>
          <pose>-3.62119 4.40316 0.099704 0.003105 -0.002028 -0.000169</pose>
          <velocity>0 0 0 0 -0 0</velocity>
          <acceleration>4.3e-05 6.6e-05 -29.4 0.826171 -0.549369 3.14159</acceleration>
          <wrench>4.3e-05 6.6e-05 -29.4 0 -0 0</wrench>
        </link>
      </model>
      <model name='right_robot'>
        <pose>0.337045 3.6469 0.123317 0 0 -1.56414</pose>
        <scale>1 1 1</scale>
        <link name='right_summit_back_left_wheel_link'>
          <pose>0.54006 3.87076 0.250317 3.14159 0.318968 1.57745</pose>
          <velocity>-0 -0 3e-06 1e-06 -3e-06 0</velocity>
          <acceleration>0 -3e-06 -0 1.4e-05 -0 0</acceleration>
          <wrench>0 -2e-05 -0 0 -0 0</wrench>
        </link>
        <link name='right_summit_back_right_wheel_link'>
          <pose>0.131069 3.86803 0.250317 3.14159 0.31445 1.57745</pose>
          <velocity>-0 -0 3e-06 1e-06 -3e-06 0</velocity>
          <acceleration>0 -3e-06 0 1.4e-05 -0 0</acceleration>
          <wrench>0 -2e-05 0 0 -0 0</wrench>
        </link>
        <link name='right_summit_base_footprint'>
          <pose>0.337045 3.6469 0.123317 0 0 -1.56414</pose>
          <velocity>-0 -0 3e-06 0 -0 0</velocity>
          <acceleration>0 -3e-06 -0 0 -0 0</acceleration>
          <wrench>3e-06 -0.000413 -0 0 -0 0</wrench>
        </link>
        <link name='right_summit_front_left_wheel_link'>
          <pose>0.543022 3.42577 0.250317 3.14159 0.323667 1.57745</pose>
          <velocity>-0 -0 3e-06 1e-06 -3e-06 0</velocity>
          <acceleration>0 -3e-06 -0 1.4e-05 -0 0</acceleration>
          <wrench>0 -2e-05 -0 0 -0 0</wrench>
        </link>
        <link name='right_summit_front_right_wheel_link'>
          <pose>0.134031 3.42304 0.250317 3.14159 0.139174 1.57745</pose>
          <velocity>-0 -0 3e-06 1e-06 -3e-06 0</velocity>
          <acceleration>0 -3e-06 0 1.4e-05 -0 0</acceleration>
          <wrench>0 -2e-05 0 0 -0 0</wrench>
        </link>
        <link name='ur_right_forearm_link'>
          <pose>0.44552 3.32781 1.08773 -1.5708 0.381349 -1.24311</pose>
          <velocity>-0 -0 3e-06 0 1e-06 0</velocity>
          <acceleration>0.000196 9.8e-05 6.3e-05 -0.001405 0.004947 0.001373</acceleration>
          <wrench>0.000557 0.000279 0.000179 0 -0 0</wrench>
        </link>
        <link name='ur_right_shoulder_link'>
          <pose>0.337045 3.6469 0.828817 0 -0 1.89848</pose>
          <velocity>-0 -0 3e-06 0 1e-06 0</velocity>
          <acceleration>-1e-06 -3e-06 5e-06 -0.000203 0.000595 -0.000123</acceleration>
          <wrench>-5e-06 -1.1e-05 2e-05 0 -0 0</wrench>
        </link>
        <link name='ur_right_upper_arm_link'>
          <pose>0.337045 3.6469 0.828817 1.5708 0.655067 1.89849</pose>
          <velocity>-0 -0 3e-06 -1e-06 1e-06 -1e-06</velocity>
          <acceleration>3.7e-05 -6e-06 -4.2e-05 -0.001548 0.004978 -0.003966</acceleration>
          <wrench>0.000297 -4.8e-05 -0.000338 0 -0 0</wrench>
        </link>
        <link name='ur_right_wrist_1_link'>
          <pose>0.454564 3.71536 1.2337 -1.5708 -0.939784 -1.2431</pose>
          <velocity>0 0 3e-06 0 1e-06 -1e-06</velocity>
          <acceleration>0.000329 9.1e-05 -3.9e-05 -5.5e-05 0.001161 -0.000453</acceleration>
          <wrench>0.000451 0.000124 -5.4e-05 0 -0 0</wrench>
        </link>
        <link name='ur_right_wrist_2_link'>
          <pose>0.428655 3.79158 1.29252 -0.939624 0.020911 0.342971</pose>
          <velocity>0 0 3e-06 -1e-06 3e-06 0</velocity>
          <acceleration>0.000427 0.000106 -1.5e-05 -0.000662 0.002773 0.000667</acceleration>
          <wrench>0.000556 0.000137 -2e-05 0 -0 0</wrench>
        </link>
        <link name='ur_right_wrist_3_link'>
          <pose>0.407307 3.84637 1.21212 -2.51059 0.026076 0.3359</pose>
          <velocity>-0 -0 3e-06 0 2e-06 1e-06</velocity>
          <acceleration>0.000193 8.2e-05 -3.7e-05 -0.0003 0.002049 0.000552</acceleration>
          <wrench>0.000148 6.3e-05 -2.8e-05 0 -0 0</wrench>
        </link>
      </model>
      <model name='target_plane'>
        <pose>6.58171 -8.56484 0.134058 0 -0 0</pose>
        <scale>1 1 1</scale>
        <link name='link_0'>
          <pose>6.58171 -8.56484 0.134058 0 -0 0</pose>
          <velocity>0 0 0 0 -0 0</velocity>
          <acceleration>-0.077371 -0.018355 -3.40919 -1.25743 -1.48499 -3.14157</acceleration>
          <wrench>-0.005832 -0.001384 -0.25697 0 -0 0</wrench>
        </link>
      </model>
      <light name='sun'>
        <pose>0 0 10 0 -0 0</pose>
      </light>
    </state>
    <model name='pallet2'>
      <pose>6.82908 -9.08928 0.07 0 -0 0</pose>
      <self_collide>0</self_collide>
      <link name='pallet_base'>
        <pose>0 0 0 0 -0 0</pose>
        <collision name='pallet_top_collision'>
          <pose>0 0 0.125 0 -0 0</pose>
          <geometry>
            <box>
              <size>1.22 0.8 0.04</size>
            </box>
          </geometry>
          <max_contacts>10</max_contacts>
          <surface>
            <contact>
              <ode/>
            </contact>
            <bounce/>
            <friction>
              <torsional>
                <ode/>
              </torsional>
              <ode/>
            </friction>
          </surface>
        </collision>
        <collision name='pallet_center_collision'>
          <pose>0 0 0.055 0 -0 0</pose>
          <geometry>
            <box>
              <size>1.22 0.1 0.1</size>
            </box>
          </geometry>
          <max_contacts>10</max_contacts>
          <surface>
            <contact>
              <ode/>
            </contact>
            <bounce/>
            <friction>
              <torsional>
                <ode/>
              </torsional>
              <ode/>
            </friction>
          </surface>
        </collision>
        <collision name='pallet_left_collision'>
          <pose>0 -0.35 0.055 0 -0 0</pose>
          <geometry>
            <box>
              <size>1.22 0.1 0.1</size>
            </box>
          </geometry>
          <max_contacts>10</max_contacts>
          <surface>
            <contact>
              <ode/>
            </contact>
            <bounce/>
            <friction>
              <torsional>
                <ode/>
              </torsional>
              <ode/>
            </friction>
          </surface>
        </collision>
        <collision name='pallet_right_collision'>
          <pose>0 0.35 0.055 0 -0 0</pose>
          <geometry>
            <box>
              <size>1.22 0.1 0.1</size>
            </box>
          </geometry>
          <max_contacts>10</max_contacts>
          <surface>
            <contact>
              <ode/>
            </contact>
            <bounce/>
            <friction>
              <torsional>
                <ode/>
              </torsional>
              <ode/>
            </friction>
          </surface>
        </collision>
        <visual name='pallet_visual'>
          <pose>0 0 0 0 -0 0</pose>
          <geometry>
            <mesh>
              <scale>1 1 1</scale>
              <uri>/ros2_ws/install/ur/share/ur/xacro/./Models/pallet/meshes/pallet.dae</uri>
            </mesh>
          </geometry>
        </visual>
        <self_collide>0</self_collide>
        <inertial>
          <pose>0 0 0 0 -0 0</pose>
          <inertia>
            <ixx>1</ixx>
            <ixy>0</ixy>
            <ixz>0</ixz>
            <iyy>1</iyy>
            <iyz>0</iyz>
            <izz>1</izz>
          </inertia>
          <mass>1</mass>
        </inertial>
        <enable_wind>0</enable_wind>
        <kinematic>0</kinematic>
      </link>
      <static>0</static>
    </model>
    <gui fullscreen='0'>
      <camera name='user_camera'>
        <pose>1.65604 4.27814 0.982508 -0 0.140246 -3.07547</pose>
        <view_controller>orbit</view_controller>
        <projection_type>perspective</projection_type>
      </camera>
    </gui>
    <model name='aws_robomaker_warehouse_GroundB_01_0'>
      <link name='link'>
        <inertial>
          <mass>1000</mass>
          <inertia>
            <ixx>1.20008e+06</ixx>
            <ixy>0</ixy>
            <ixz>0</ixz>
            <iyy>8.33342e+06</iyy>
            <iyz>0</iyz>
            <izz>2.03333e+06</izz>
          </inertia>
        </inertial>
        <collision name='collision'>
          <geometry>
            <mesh>
              <uri>/ros2_ws/install/ur/share/ur/xacro/./Models/aws_warehouse/aws_robomaker_warehouse_GroundB_01/meshes/aws_robomaker_warehouse_GroundB_01_collision.DAE</uri>
              <scale>1 1 1</scale>
            </mesh>
          </geometry>
          <surface>
            <friction>
              <ode>
                <mu>100</mu>
                <mu2>50</mu2>
                <fdir1>0 0 0</fdir1>
                <slip1>0</slip1>
                <slip2>0</slip2>
              </ode>
              <torsional>
                <ode/>
              </torsional>
            </friction>
            <contact>
              <ode/>
            </contact>
            <bounce/>
          </surface>
          <max_contacts>10</max_contacts>
        </collision>
        <visual name='visual'>
          <geometry>
            <mesh>
              <uri>/ros2_ws/install/ur/share/ur/xacro/./Models/aws_warehouse/aws_robomaker_warehouse_GroundB_01/meshes/aws_robomaker_warehouse_GroundB_01_visual.DAE</uri>
            </mesh>
          </geometry>
          <meta>
            <layer>1</layer>
          </meta>
        </visual>
        <self_collide>0</self_collide>
        <enable_wind>0</enable_wind>
        <kinematic>0</kinematic>
      </link>
      <static>1</static>
      <pose>0 -0.442162 0 0 -0 0</pose>
    </model>
    <model name='target_plane'>
      <link name='link_0'>
        <inertial>
          <mass>0.0753756</mass>
          <inertia>
            <ixx>0.0242871</ixx>
            <ixy>0</ixy>
            <ixz>0</ixz>
            <iyy>0.0244094</iyy>
            <iyz>0</iyz>
            <izz>0.0486918</izz>
          </inertia>
          <pose>0 0 0 0 -0 0</pose>
        </inertial>
        <pose>-0 -0 0 0 -0 0</pose>
        <gravity>1</gravity>
        <self_collide>0</self_collide>
        <kinematic>0</kinematic>
        <enable_wind>0</enable_wind>
        <visual name='visual'>
          <pose>0 0 0 0 -0 0</pose>
          <geometry>
            <box>
              <size>1.97121 1.96626 0.019484</size>
            </box>
          </geometry>
          <material>
            <lighting>1</lighting>
            <script>
              <uri>file://media/materials/scripts/gazebo.material</uri>
              <name>Gazebo/Grey</name>
            </script>
            <shader type='pixel'>
              <normal_map>__default__</normal_map>
            </shader>
            <ambient>0.961 0.761 0.067 1</ambient>
            <diffuse>0.961 0.761 0.067 1</diffuse>
            <specular>0.961 0.761 0.067 1</specular>
            <emissive>0.961 0.761 0.067 1</emissive>
          </material>
          <transparency>0</transparency>
          <cast_shadows>1</cast_shadows>
        </visual>
        <collision name='collision'>
          <laser_retro>0</laser_retro>
          <max_contacts>10</max_contacts>
          <pose>0 0 0 0 -0 0</pose>
          <geometry>
            <box>
              <size>1.97121 1.96626 0.019484</size>
            </box>
          </geometry>
          <surface>
            <friction>
              <ode>
                <mu>1</mu>
                <mu2>1</mu2>
                <fdir1>0 0 0</fdir1>
                <slip1>0</slip1>
                <slip2>0</slip2>
              </ode>
              <torsional>
                <coefficient>1</coefficient>
                <patch_radius>0</patch_radius>
                <surface_radius>0</surface_radius>
                <use_patch_radius>1</use_patch_radius>
                <ode>
                  <slip>0</slip>
                </ode>
              </torsional>
            </friction>
            <bounce>
              <restitution_coefficient>0</restitution_coefficient>
              <threshold>1e+06</threshold>
            </bounce>
            <contact>
              <collide_without_contact>0</collide_without_contact>
              <collide_without_contact_bitmask>1</collide_without_contact_bitmask>
              <collide_bitmask>1</collide_bitmask>
              <ode>
                <soft_cfm>0</soft_cfm>
                <soft_erp>0.2</soft_erp>
                <kp>1e+13</kp>
                <kd>1</kd>
                <max_vel>0.01</max_vel>
                <min_depth>0</min_depth>
              </ode>
              <bullet>
                <split_impulse>1</split_impulse>
                <split_impulse_penetration_threshold>-0.01</split_impulse_penetration_threshold>
                <soft_cfm>0</soft_cfm>
                <soft_erp>0.2</soft_erp>
                <kp>1e+13</kp>
                <kd>1</kd>
              </bullet>
            </contact>
          </surface>
        </collision>
      </link>
      <static>0</static>
      <allow_auto_disable>1</allow_auto_disable>
      <pose>9.00801 -7.68181 0 0 -0 0</pose>
    </model>
    <model name='pacco'>
      <link name='link_1'>
        <inertial>
          <mass>1</mass>
          <inertia>
            <ixx>0.166667</ixx>
            <ixy>0</ixy>
            <ixz>0</ixz>
            <iyy>0.166667</iyy>
            <iyz>0</iyz>
            <izz>0.166667</izz>
          </inertia>
          <pose>0 0 0 0 -0 0</pose>
        </inertial>
        <pose>0 -0 0 0 -0 0</pose>
        <gravity>1</gravity>
        <self_collide>0</self_collide>
        <kinematic>0</kinematic>
        <enable_wind>0</enable_wind>
        <visual name='visual'>
          <pose>0 0 0 0 -0 0</pose>
          <geometry>
            <mesh>
              <uri>/ros2_ws/install/ur/share/ur/xacro/./Models/package_800x300x200/package.dae</uri>
              <scale>1 1 1</scale>
            </mesh>
          </geometry>
          <material>
            <lighting>1</lighting>
            <script>
              <uri>file://media/materials/scripts/gazebo.material</uri>
              <name>Gazebo/Grey</name>
            </script>
            <shader type='pixel'>
              <normal_map>__default__</normal_map>
            </shader>
            <ambient>0.6 0 0 0</ambient>
            <diffuse>0.5 0.7 0.7 1</diffuse>
            <specular>0.01 0.01 0.01 1</specular>
            <emissive>0 0 0 1</emissive>
          </material>
          <transparency>0</transparency>
          <cast_shadows>1</cast_shadows>
        </visual>
        <collision name='collision_1'>
          <laser_retro>0</laser_retro>
          <max_contacts>10</max_contacts>
          <pose>0 0 0 0 -0 0</pose>
          <geometry>
            <box>
              <size>0.8 0.3 0.2</size>
            </box>
          </geometry>
          <surface>
            <friction>
              <ode>
                <mu>1</mu>
                <mu2>1</mu2>
                <fdir1>0 0 0</fdir1>
                <slip1>0</slip1>
                <slip2>0</slip2>
              </ode>
              <torsional>
                <coefficient>1</coefficient>
                <patch_radius>0</patch_radius>
                <surface_radius>0</surface_radius>
                <use_patch_radius>1</use_patch_radius>
                <ode>
                  <slip>0</slip>
                </ode>
              </torsional>
            </friction>
            <bounce>
              <restitution_coefficient>0</restitution_coefficient>
              <threshold>1e+06</threshold>
            </bounce>
            <contact>
              <collide_without_contact>0</collide_without_contact>
              <collide_without_contact_bitmask>1</collide_without_contact_bitmask>
              <collide_bitmask>1</collide_bitmask>
              <ode>
                <soft_cfm>0</soft_cfm>
                <soft_erp>0.2</soft_erp>
                <kp>1e+13</kp>
                <kd>1</kd>
                <max_vel>0.01</max_vel>
                <min_depth>0</min_depth>
              </ode>
              <bullet>
                <split_impulse>1</split_impulse>
                <split_impulse_penetration_threshold>-0.01</split_impulse_penetration_threshold>
                <soft_cfm>0</soft_cfm>
                <soft_erp>0.2</soft_erp>
                <kp>1e+13</kp>
                <kd>1</kd>
              </bullet>
            </contact>
          </surface>
        </collision>
      </link>
      <static>0</static>
      <allow_auto_disable>1</allow_auto_disable>
      <pose>-0.267458 2.18834 0.631591 0 -0 0</pose>
    </model>
    <model name='pacco_clone'>
      <link name='link_1'>
        <inertial>
          <mass>1</mass>
          <inertia>
            <ixx>0.166667</ixx>
            <ixy>0</ixy>
            <ixz>0</ixz>
            <iyy>0.166667</iyy>
            <iyz>0</iyz>
            <izz>0.166667</izz>
          </inertia>
          <pose>0 0 0 0 -0 0</pose>
        </inertial>
        <pose>0 -0 0 0 -0 0</pose>
        <gravity>1</gravity>
        <self_collide>0</self_collide>
        <kinematic>0</kinematic>
        <enable_wind>0</enable_wind>
        <visual name='visual'>
          <pose>0 0 0 0 -0 0</pose>
          <geometry>
            <mesh>
              <uri>/ros2_ws/install/ur/share/ur/xacro/./Models/package_800x300x200/package.dae</uri>
              <scale>1 1 1</scale>
            </mesh>
          </geometry>
          <material>
            <lighting>1</lighting>
            <script>
              <uri>file://media/materials/scripts/gazebo.material</uri>
              <name>Gazebo/Grey</name>
            </script>
            <shader type='pixel'>
              <normal_map>__default__</normal_map>
            </shader>
            <ambient>0.6 0 0 0</ambient>
            <diffuse>0.5 0.7 0.7 1</diffuse>
            <specular>0.01 0.01 0.01 1</specular>
            <emissive>0 0 0 1</emissive>
          </material>
          <transparency>0</transparency>
          <cast_shadows>1</cast_shadows>
        </visual>
        <collision name='collision_1'>
          <laser_retro>0</laser_retro>
          <max_contacts>10</max_contacts>
          <pose>0 0 0 0 -0 0</pose>
          <geometry>
            <box>
              <size>0.8 0.3 0.2</size>
            </box>
          </geometry>
          <surface>
            <friction>
              <ode>
                <mu>1</mu>
                <mu2>1</mu2>
                <fdir1>0 0 0</fdir1>
                <slip1>0</slip1>
                <slip2>0</slip2>
              </ode>
              <torsional>
                <coefficient>1</coefficient>
                <patch_radius>0</patch_radius>
                <surface_radius>0</surface_radius>
                <use_patch_radius>1</use_patch_radius>
                <ode>
                  <slip>0</slip>
                </ode>
              </torsional>
            </friction>
            <bounce>
              <restitution_coefficient>0</restitution_coefficient>
              <threshold>1e+06</threshold>
            </bounce>
            <contact>
              <collide_without_contact>0</collide_without_contact>
              <collide_without_contact_bitmask>1</collide_without_contact_bitmask>
              <collide_bitmask>1</collide_bitmask>
              <ode>
                <soft_cfm>0</soft_cfm>
                <soft_erp>0.2</soft_erp>
                <kp>1e+13</kp>
                <kd>1</kd>
                <max_vel>0.01</max_vel>
                <min_depth>0</min_depth>
              </ode>
              <bullet>
                <split_impulse>1</split_impulse>
                <split_impulse_penetration_threshold>-0.01</split_impulse_penetration_threshold>
                <soft_cfm>0</soft_cfm>
                <soft_erp>0.2</soft_erp>
                <kp>1e+13</kp>
                <kd>1</kd>
              </bullet>
            </contact>
          </surface>
        </collision>
      </link>
      <static>0</static>
      <allow_auto_disable>1</allow_auto_disable>
      <pose>-0.252861 5.5362 0.86 0 -0 0</pose>
    </model>
    <model name='pacco_clone_0'>
      <link name='link_1'>
        <inertial>
          <mass>1</mass>
          <inertia>
            <ixx>0.166667</ixx>
            <ixy>0</ixy>
            <ixz>0</ixz>
            <iyy>0.166667</iyy>
            <iyz>0</iyz>
            <izz>0.166667</izz>
          </inertia>
          <pose>0 0 0 0 -0 0</pose>
        </inertial>
        <pose>0 -0 0 0 -0 0</pose>
        <gravity>1</gravity>
        <self_collide>0</self_collide>
        <kinematic>0</kinematic>
        <enable_wind>0</enable_wind>
        <visual name='visual'>
          <pose>0 0 0 0 -0 0</pose>
          <geometry>
            <mesh>
              <uri>/ros2_ws/install/ur/share/ur/xacro/./Models/package_800x300x200/package.dae</uri>
              <scale>1 1 1</scale>
            </mesh>
          </geometry>
          <material>
            <lighting>1</lighting>
            <script>
              <uri>file://media/materials/scripts/gazebo.material</uri>
              <name>Gazebo/Grey</name>
            </script>
            <shader type='pixel'>
              <normal_map>__default__</normal_map>
            </shader>
            <ambient>0.6 0 0 0</ambient>
            <diffuse>0.5 0.7 0.7 1</diffuse>
            <specular>0.01 0.01 0.01 1</specular>
            <emissive>0 0 0 1</emissive>
          </material>
          <transparency>0</transparency>
          <cast_shadows>1</cast_shadows>
        </visual>
        <collision name='collision_1'>
          <laser_retro>0</laser_retro>
          <max_contacts>10</max_contacts>
          <pose>0 0 0 0 -0 0</pose>
          <geometry>
            <box>
              <size>0.8 0.3 0.2</size>
            </box>
          </geometry>
          <surface>
            <friction>
              <ode>
                <mu>1</mu>
                <mu2>1</mu2>
                <fdir1>0 0 0</fdir1>
                <slip1>0</slip1>
                <slip2>0</slip2>
              </ode>
              <torsional>
                <coefficient>1</coefficient>
                <patch_radius>0</patch_radius>
                <surface_radius>0</surface_radius>
                <use_patch_radius>1</use_patch_radius>
                <ode>
                  <slip>0</slip>
                </ode>
              </torsional>
            </friction>
            <bounce>
              <restitution_coefficient>0</restitution_coefficient>
              <threshold>1e+06</threshold>
            </bounce>
            <contact>
              <collide_without_contact>0</collide_without_contact>
              <collide_without_contact_bitmask>1</collide_without_contact_bitmask>
              <collide_bitmask>1</collide_bitmask>
              <ode>
                <soft_cfm>0</soft_cfm>
                <soft_erp>0.2</soft_erp>
                <kp>1e+13</kp>
                <kd>1</kd>
                <max_vel>0.01</max_vel>
                <min_depth>0</min_depth>
              </ode>
              <bullet>
                <split_impulse>1</split_impulse>
                <split_impulse_penetration_threshold>-0.01</split_impulse_penetration_threshold>
                <soft_cfm>0</soft_cfm>
                <soft_erp>0.2</soft_erp>
                <kp>1e+13</kp>
                <kd>1</kd>
              </bullet>
            </contact>
          </surface>
        </collision>
      </link>
      <static>0</static>
      <allow_auto_disable>1</allow_auto_disable>
      <pose>-0.241431 5.19278 0.86 0 -0 0</pose>
    </model>
    <model name='pacco_clone_1'>
      <link name='link_1'>
        <inertial>
          <mass>1</mass>
          <inertia>
            <ixx>0.166667</ixx>
            <ixy>0</ixy>
            <ixz>0</ixz>
            <iyy>0.166667</iyy>
            <iyz>0</iyz>
            <izz>0.166667</izz>
          </inertia>
          <pose>0 0 0 0 -0 0</pose>
        </inertial>
        <pose>0 -0 0 0 -0 0</pose>
        <gravity>1</gravity>
        <self_collide>0</self_collide>
        <kinematic>0</kinematic>
        <enable_wind>0</enable_wind>
        <visual name='visual'>
          <pose>0 0 0 0 -0 0</pose>
          <geometry>
            <mesh>
              <uri>/ros2_ws/install/ur/share/ur/xacro/./Models/package_800x300x200/package.dae</uri>
              <scale>1 1 1</scale>
            </mesh>
          </geometry>
          <material>
            <lighting>1</lighting>
            <script>
              <uri>file://media/materials/scripts/gazebo.material</uri>
              <name>Gazebo/Grey</name>
            </script>
            <shader type='pixel'>
              <normal_map>__default__</normal_map>
            </shader>
            <ambient>0.6 0 0 0</ambient>
            <diffuse>0.5 0.7 0.7 1</diffuse>
            <specular>0.01 0.01 0.01 1</specular>
            <emissive>0 0 0 1</emissive>
          </material>
          <transparency>0</transparency>
          <cast_shadows>1</cast_shadows>
        </visual>
        <collision name='collision_1'>
          <laser_retro>0</laser_retro>
          <max_contacts>10</max_contacts>
          <pose>0 0 0 0 -0 0</pose>
          <geometry>
            <box>
              <size>0.8 0.3 0.2</size>
            </box>
          </geometry>
          <surface>
            <friction>
              <ode>
                <mu>1</mu>
                <mu2>1</mu2>
                <fdir1>0 0 0</fdir1>
                <slip1>0</slip1>
                <slip2>0</slip2>
              </ode>
              <torsional>
                <coefficient>1</coefficient>
                <patch_radius>0</patch_radius>
                <surface_radius>0</surface_radius>
                <use_patch_radius>1</use_patch_radius>
                <ode>
                  <slip>0</slip>
                </ode>
              </torsional>
            </friction>
            <bounce>
              <restitution_coefficient>0</restitution_coefficient>
              <threshold>1e+06</threshold>
            </bounce>
            <contact>
              <collide_without_contact>0</collide_without_contact>
              <collide_without_contact_bitmask>1</collide_without_contact_bitmask>
              <collide_bitmask>1</collide_bitmask>
              <ode>
                <soft_cfm>0</soft_cfm>
                <soft_erp>0.2</soft_erp>
                <kp>1e+13</kp>
                <kd>1</kd>
                <max_vel>0.01</max_vel>
                <min_depth>0</min_depth>
              </ode>
              <bullet>
                <split_impulse>1</split_impulse>
                <split_impulse_penetration_threshold>-0.01</split_impulse_penetration_threshold>
                <soft_cfm>0</soft_cfm>
                <soft_erp>0.2</soft_erp>
                <kp>1e+13</kp>
                <kd>1</kd>
              </bullet>
            </contact>
          </surface>
        </collision>
      </link>
      <static>0</static>
      <allow_auto_disable>1</allow_auto_disable>
      <pose>-0.230611 4.86775 0.86 0 -0 0</pose>
    </model>
    <model name='pacco_clone_2'>
      <link name='link_1'>
        <inertial>
          <mass>1</mass>
          <inertia>
            <ixx>0.166667</ixx>
            <ixy>0</ixy>
            <ixz>0</ixz>
            <iyy>0.166667</iyy>
            <iyz>0</iyz>
            <izz>0.166667</izz>
          </inertia>
          <pose>0 0 0 0 -0 0</pose>
        </inertial>
        <pose>0 -0 0 0 -0 0</pose>
        <gravity>1</gravity>
        <self_collide>0</self_collide>
        <kinematic>0</kinematic>
        <enable_wind>0</enable_wind>
        <visual name='visual'>
          <pose>0 0 0 0 -0 0</pose>
          <geometry>
            <mesh>
              <uri>/ros2_ws/install/ur/share/ur/xacro/./Models/package_800x300x200/package.dae</uri>
              <scale>1 1 1</scale>
            </mesh>
          </geometry>
          <material>
            <lighting>1</lighting>
            <script>
              <uri>file://media/materials/scripts/gazebo.material</uri>
              <name>Gazebo/Grey</name>
            </script>
            <shader type='pixel'>
              <normal_map>__default__</normal_map>
            </shader>
            <ambient>0.6 0 0 0</ambient>
            <diffuse>0.5 0.7 0.7 1</diffuse>
            <specular>0.01 0.01 0.01 1</specular>
            <emissive>0 0 0 1</emissive>
          </material>
          <transparency>0</transparency>
          <cast_shadows>1</cast_shadows>
        </visual>
        <collision name='collision_1'>
          <laser_retro>0</laser_retro>
          <max_contacts>10</max_contacts>
          <pose>0 0 0 0 -0 0</pose>
          <geometry>
            <box>
              <size>0.8 0.3 0.2</size>
            </box>
          </geometry>
          <surface>
            <friction>
              <ode>
                <mu>1</mu>
                <mu2>1</mu2>
                <fdir1>0 0 0</fdir1>
                <slip1>0</slip1>
                <slip2>0</slip2>
              </ode>
              <torsional>
                <coefficient>1</coefficient>
                <patch_radius>0</patch_radius>
                <surface_radius>0</surface_radius>
                <use_patch_radius>1</use_patch_radius>
                <ode>
                  <slip>0</slip>
                </ode>
              </torsional>
            </friction>
            <bounce>
              <restitution_coefficient>0</restitution_coefficient>
              <threshold>1e+06</threshold>
            </bounce>
            <contact>
              <collide_without_contact>0</collide_without_contact>
              <collide_without_contact_bitmask>1</collide_without_contact_bitmask>
              <collide_bitmask>1</collide_bitmask>
              <ode>
                <soft_cfm>0</soft_cfm>
                <soft_erp>0.2</soft_erp>
                <kp>1e+13</kp>
                <kd>1</kd>
                <max_vel>0.01</max_vel>
                <min_depth>0</min_depth>
              </ode>
              <bullet>
                <split_impulse>1</split_impulse>
                <split_impulse_penetration_threshold>-0.01</split_impulse_penetration_threshold>
                <soft_cfm>0</soft_cfm>
                <soft_erp>0.2</soft_erp>
                <kp>1e+13</kp>
                <kd>1</kd>
              </bullet>
            </contact>
          </surface>
        </collision>
      </link>
      <static>0</static>
      <allow_auto_disable>1</allow_auto_disable>
      <pose>-3.72777 4.24036 0.86 0 -0 0</pose>
    </model>
    <model name='muraUse1'>
      <link name='link_0'>
        <inertial>
          <mass>100</mass>
          <inertia>
            <ixx>0</ixx>
            <ixy>0</ixy>
            <ixz>0</ixz>
            <iyy>0</iyy>
            <iyz>0</iyz>
            <izz>0</izz>
          </inertia>
          <pose>0 0 0 0 -0 0</pose>
        </inertial>
        <pose>0 0 0 0 0 -1.57075</pose>
        <gravity>1</gravity>
        <self_collide>0</self_collide>
        <kinematic>0</kinematic>
        <enable_wind>0</enable_wind>
        <visual name='visual'>
          <pose>0 0 0 0 -0 0</pose>
          <geometry>
            <mesh>
              <uri>/ros2_ws/assets/usecase1(mura+pallet).stl</uri>
              <scale>1 1 1</scale>
            </mesh>
          </geometry>
          <material>
            <lighting>1</lighting>
            <script>
              <uri>file://media/materials/scripts/gazebo.material</uri>
              <name>Gazebo/Grey</name>
            </script>
            <shader type='pixel'>
              <normal_map>__default__</normal_map>
            </shader>
          </material>
          <transparency>0</transparency>
          <cast_shadows>1</cast_shadows>
        </visual>
        <collision name='collision'>
          <laser_retro>0</laser_retro>
          <max_contacts>10</max_contacts>
          <pose>0 0 0 0 -0 0</pose>
          <geometry>
            <mesh>
              <uri>/ros2_ws/assets/usecase1(mura+pallet).stl</uri>
              <scale>1 1 1</scale>
            </mesh>
          </geometry>
          <surface>
            <friction>
              <ode>
                <mu>5000</mu>
                <mu2>5000</mu2>
                <fdir1>0 0 0</fdir1>
                <slip1>0</slip1>
                <slip2>0</slip2>
              </ode>
              <torsional>
                <coefficient>1</coefficient>
                <patch_radius>0</patch_radius>
                <surface_radius>0</surface_radius>
                <use_patch_radius>1</use_patch_radius>
                <ode>
                  <slip>0</slip>
                </ode>
              </torsional>
            </friction>
            <bounce>
              <restitution_coefficient>0</restitution_coefficient>
              <threshold>1e+06</threshold>
            </bounce>
            <contact>
              <collide_without_contact>0</collide_without_contact>
              <collide_without_contact_bitmask>1</collide_without_contact_bitmask>
              <collide_bitmask>1</collide_bitmask>
              <ode>
                <soft_cfm>0</soft_cfm>
                <soft_erp>0.2</soft_erp>
                <kp>1e+13</kp>
                <kd>1</kd>
                <max_vel>0.01</max_vel>
                <min_depth>0</min_depth>
              </ode>
              <bullet>
                <split_impulse>1</split_impulse>
                <split_impulse_penetration_threshold>-0.01</split_impulse_penetration_threshold>
                <soft_cfm>0</soft_cfm>
                <soft_erp>0.2</soft_erp>
                <kp>1e+13</kp>
                <kd>1</kd>
              </bullet>
            </contact>
          </surface>
        </collision>
      </link>
      <static>0</static>
      <allow_auto_disable>1</allow_auto_disable>
      <pose>1.72555 4.14006 0 0 -0 0</pose>
    </model>
    <model name='left_robot'>
      <link name='left_summit_base_footprint'>
        <inertial>
          <pose>5e-06 -5e-06 0.14373 0 -0 0</pose>
          <mass>131.405</mass>
          <inertia>
            <ixx>2.28126</ixx>
            <ixy>0.147666</ixy>
            <ixz>-0.000130347</ixz>
            <iyy>7.83548</iyy>
            <iyz>0.000132399</iyz>
            <izz>6.43846</izz>
          </inertia>
        </inertial>
        <collision name='left_summit_base_footprint_fixed_joint_lump__left_summit_base_link_collision'>
          <pose>0 0 0.127 0 -0 0</pose>
          <geometry>
            <mesh>
              <scale>1 1 1</scale>
              <uri>file:///ros2_ws/install/summit_xl_description/share/summit_xl_description/meshes/bases/xls/summit_xls_chassis.dae</uri>
            </mesh>
          </geometry>
          <surface>
            <contact>
              <ode/>
            </contact>
            <friction>
              <ode/>
              <torsional>
                <ode/>
              </torsional>
            </friction>
            <bounce/>
          </surface>
          <max_contacts>10</max_contacts>
        </collision>
        <collision name='left_summit_base_footprint_fixed_joint_lump__left_summit_front_laser_base_link_collision_1'>
          <pose>0.2865 -0.20894 0.4243 3.14159 -0 -0.785398</pose>
          <geometry>
            <mesh>
              <scale>1 1 1</scale>
              <uri>model://robotnik_sensors/meshes/sick_s300.dae</uri>
            </mesh>
          </geometry>
          <max_contacts>10</max_contacts>
          <surface>
            <contact>
              <ode/>
            </contact>
            <bounce/>
            <friction>
              <torsional>
                <ode/>
              </torsional>
              <ode/>
            </friction>
          </surface>
        </collision>
        <collision name='left_summit_base_footprint_fixed_joint_lump__left_summit_rear_laser_base_link_collision_2'>
          <pose>-0.2865 0.20894 0.4243 3.14159 -0 2.35619</pose>
          <geometry>
            <mesh>
              <scale>1 1 1</scale>
              <uri>model://robotnik_sensors/meshes/sick_s300.dae</uri>
            </mesh>
          </geometry>
          <max_contacts>10</max_contacts>
          <surface>
            <contact>
              <ode/>
            </contact>
            <bounce/>
            <friction>
              <torsional>
                <ode/>
              </torsional>
              <ode/>
            </friction>
          </surface>
        </collision>
        <collision name='left_summit_base_footprint_fixed_joint_lump__ur_left_base_link_inertia_collision_3'>
          <pose>0 0 0.543 0 0 -1.57</pose>
          <geometry>
            <mesh>
              <scale>1 1 1</scale>
              <uri>file:///ros2_ws/install/ur_description/share/ur_description/meshes/ur5e/collision/base.stl</uri>
            </mesh>
          </geometry>
          <max_contacts>10</max_contacts>
          <surface>
            <contact>
              <ode/>
            </contact>
            <bounce/>
            <friction>
              <torsional>
                <ode/>
              </torsional>
              <ode/>
            </friction>
          </surface>
        </collision>
        <visual name='left_summit_base_footprint_visual'>
          <pose>0 0 0.5 0 -0 0</pose>
          <geometry>
            <box>
              <size>0.001 0.001 0.001</size>
            </box>
          </geometry>
        </visual>
        <visual name='left_summit_base_footprint_fixed_joint_lump__left_summit_base_link_visual_1'>
          <pose>0 0 0.127 0 -0 0</pose>
          <geometry>
            <mesh>
              <scale>1 1 1</scale>
              <uri>file:///ros2_ws/install/summit_xl_description/share/summit_xl_description/meshes/bases/xls/summit_xls_chassis.stl</uri>
            </mesh>
          </geometry>
          <material>
            <script>
              <name>Gazebo/Black</name>
              <uri>file://media/materials/scripts/gazebo.material</uri>
            </script>
          </material>
        </visual>
        <visual name='left_summit_base_footprint_fixed_joint_lump__left_summit_base_logo_front_visual_2'>
          <pose>0.345 0 0.127 0 0 -1.5708</pose>
          <geometry>
            <mesh>
              <scale>1 1 1</scale>
              <uri>file:///ros2_ws/install/summit_xl_description/share/summit_xl_description/meshes/bases/xls/robotnik_logo_chasis.stl</uri>
            </mesh>
          </geometry>
        </visual>
        <visual name='left_summit_base_footprint_fixed_joint_lump__left_summit_base_logo_left_visual_3'>
          <pose>0 0.28931 0.41762 0 -0 0</pose>
          <geometry>
            <mesh>
              <scale>1 1 1</scale>
              <uri>file:///ros2_ws/install/summit_xl_description/share/summit_xl_description/meshes/bases/xls/robotnik_logo_chasis.stl</uri>
            </mesh>
          </geometry>
        </visual>
        <visual name='left_summit_base_footprint_fixed_joint_lump__left_summit_base_logo_rear_visual_4'>
          <pose>-0.345 0 0.127 0 -0 1.5708</pose>
          <geometry>
            <mesh>
              <scale>1 1 1</scale>
              <uri>file:///ros2_ws/install/summit_xl_description/share/summit_xl_description/meshes/bases/xls/robotnik_logo_chasis.stl</uri>
            </mesh>
          </geometry>
        </visual>
        <visual name='left_summit_base_footprint_fixed_joint_lump__left_summit_base_logo_right_visual_5'>
          <pose>0 -0.28931 0.41762 0 -0 3.14159</pose>
          <geometry>
            <mesh>
              <scale>1 1 1</scale>
              <uri>file:///ros2_ws/install/summit_xl_description/share/summit_xl_description/meshes/bases/xls/robotnik_logo_chasis.stl</uri>
            </mesh>
          </geometry>
        </visual>
        <visual name='left_summit_base_footprint_fixed_joint_lump__left_summit_base_chapa_visual_6'>
          <pose>0 0 0.50762 0 -0 0</pose>
          <geometry>
            <mesh>
              <scale>1 1 1</scale>
              <uri>file:///ros2_ws/install/summit_xl_description/share/summit_xl_description/meshes/bases/xls/summit_xls_chapas_inox_tapas.stl</uri>
            </mesh>
          </geometry>
        </visual>
        <visual name='left_summit_base_footprint_fixed_joint_lump__left_summit_front_laser_base_link_visual_7'>
          <pose>0.2865 -0.20894 0.4243 1.5708 -0 -0.785398</pose>
          <geometry>
            <mesh>
              <scale>1 1 1</scale>
              <uri>model://robotnik_sensors/meshes/sick_s300_color.dae</uri>
            </mesh>
          </geometry>
        </visual>
        <visual name='left_summit_base_footprint_fixed_joint_lump__left_summit_imu_link_visual_8'>
          <pose>0.127 -0.129 0.339 0 -0 0</pose>
          <geometry>
            <box>
              <size>0.001 0.001 0.001</size>
            </box>
          </geometry>
        </visual>
        <visual name='left_summit_base_footprint_fixed_joint_lump__left_summit_rear_laser_base_link_visual_9'>
          <pose>-0.2865 0.20894 0.4243 1.5708 -0 2.35619</pose>
          <geometry>
            <mesh>
              <scale>1 1 1</scale>
              <uri>model://robotnik_sensors/meshes/sick_s300_color.dae</uri>
            </mesh>
          </geometry>
        </visual>
        <visual name='left_summit_base_footprint_fixed_joint_lump__ur_left_base_link_inertia_visual_10'>
          <pose>0 0 0.543 0 0 -1.57</pose>
          <geometry>
            <mesh>
              <scale>1 1 1</scale>
              <uri>file:///ros2_ws/install/ur_description/share/ur_description/meshes/ur5e/visual/base.dae</uri>
            </mesh>
          </geometry>
        </visual>
        <gravity>0</gravity>
        <sensor name='left_summit_front_laser_sensor' type='ray'>
          <visualize>0</visualize>
          <update_rate>12.5</update_rate>
          <ray>
            <scan>
              <horizontal>
                <samples>541</samples>
                <resolution>1</resolution>
                <min_angle>-2.3562</min_angle>
                <max_angle>2.3562</max_angle>
              </horizontal>
              <vertical>
                <samples>1</samples>
                <min_angle>0</min_angle>
                <max_angle>0</max_angle>
              </vertical>
            </scan>
            <range>
              <min>0.1</min>
              <max>30</max>
              <resolution>0.03</resolution>
            </range>
            <noise>
              <type>gaussian</type>
              <mean>0</mean>
              <stddev>0.03</stddev>
            </noise>
          </ray>
          <plugin name='left_summit_front_laser_controller' filename='libgazebo_ros_ray_sensor.so'>
            <ros>
              <remapping>~/out:=front_laser/scan</remapping>
            </ros>
            <frame_name>left_summit_front_laser_link</frame_name>
            <output_type>sensor_msgs/LaserScan</output_type>
          </plugin>
          <pose>0.2865 -0.20894 0.3083 3.14159 -0 -0.785398</pose>
        </sensor>
        <gravity>1</gravity>
        <sensor name='left_summit_imu_imu_sensor' type='imu'>
          <always_on>1</always_on>
          <update_rate>100</update_rate>
          <visualize>1</visualize>
          <topic>__default_topic__</topic>
          <plugin name='left_summit_imu_imu_plugin' filename='libgazebo_ros_imu_sensor.so'>
            <topicName>imu/data</topicName>
            <bodyName>left_summit_imu_link</bodyName>
            <updateRateHZ>100.0</updateRateHZ>
            <gaussianNoise>0.0</gaussianNoise>
            <xyzOffset>0 0 0</xyzOffset>
            <rpyOffset>0 0 0</rpyOffset>
            <frameName>left_summit_imu_link</frameName>
          </plugin>
          <pose>0.127 -0.129 0.339 0 -0 0</pose>
          <imu/>
        </sensor>
        <sensor name='left_summit_rear_laser_sensor' type='ray'>
          <visualize>0</visualize>
          <update_rate>12.5</update_rate>
          <ray>
            <scan>
              <horizontal>
                <samples>541</samples>
                <resolution>1</resolution>
                <min_angle>-2.3562</min_angle>
                <max_angle>2.3562</max_angle>
              </horizontal>
              <vertical>
                <samples>1</samples>
                <min_angle>0</min_angle>
                <max_angle>0</max_angle>
              </vertical>
            </scan>
            <range>
              <min>0.1</min>
              <max>30</max>
              <resolution>0.03</resolution>
            </range>
            <noise>
              <type>gaussian</type>
              <mean>0</mean>
              <stddev>0.03</stddev>
            </noise>
          </ray>
          <plugin name='left_summit_rear_laser_controller' filename='libgazebo_ros_ray_sensor.so'>
            <ros>
              <remapping>~/out:=rear_laser/scan</remapping>
            </ros>
            <frame_name>left_summit_rear_laser_link</frame_name>
            <output_type>sensor_msgs/LaserScan</output_type>
          </plugin>
          <pose>-0.2865 0.20894 0.3083 3.14159 -0 2.35619</pose>
        </sensor>
        <self_collide>0</self_collide>
        <enable_wind>0</enable_wind>
        <kinematic>0</kinematic>
      </link>
      <joint name='left_summit_back_left_wheel_joint' type='revolute'>
        <pose relative_to='left_summit_base_footprint'>-0.2225 0.2045 0.127 0 -0 0</pose>
        <parent>left_summit_base_footprint</parent>
        <child>left_summit_back_left_wheel_link</child>
        <axis>
          <xyz>0 1 0</xyz>
          <limit>
            <effort>100</effort>
            <velocity>100</velocity>
            <lower>-1e+16</lower>
            <upper>1e+16</upper>
          </limit>
          <dynamics>
            <spring_reference>0</spring_reference>
            <spring_stiffness>0</spring_stiffness>
          </dynamics>
        </axis>
      </joint>
      <link name='left_summit_back_left_wheel_link'>
        <pose relative_to='left_summit_back_left_wheel_joint'>0 0 0 0 -0 0</pose>
        <inertial>
          <pose>0 0 0 0 -0 0</pose>
          <mass>6.5</mass>
          <inertia>
            <ixx>0.0303095</ixx>
            <ixy>0</ixy>
            <ixz>0</ixz>
            <iyy>0.0524193</iyy>
            <iyz>0</iyz>
            <izz>0.0303095</izz>
          </inertia>
        </inertial>
        <collision name='left_summit_back_left_wheel_link_collision'>
          <pose>0 0 0 1.5708 -0 0</pose>
          <geometry>
            <cylinder>
              <length>0.087</length>
              <radius>0.127</radius>
            </cylinder>
          </geometry>
          <surface>
            <contact>
              <ode>
                <kp>1e+08</kp>
                <kd>1</kd>
                <min_depth>0.001</min_depth>
              </ode>
            </contact>
            <friction>
              <ode>
                <mu>0.9</mu>
                <mu2>0.9</mu2>
              </ode>
              <torsional>
                <ode/>
              </torsional>
            </friction>
            <bounce/>
          </surface>
          <max_contacts>10</max_contacts>
        </collision>
        <visual name='left_summit_back_left_wheel_link_visual'>
          <pose>0 0 0 0 -0 0</pose>
          <geometry>
            <mesh>
              <scale>1 1 1</scale>
              <uri>file:///ros2_ws/install/summit_xl_description/share/summit_xl_description/meshes/wheels/omni_wheel_1.dae</uri>
            </mesh>
          </geometry>
        </visual>
        <self_collide>0</self_collide>
        <enable_wind>0</enable_wind>
        <kinematic>0</kinematic>
      </link>
      <joint name='left_summit_back_right_wheel_joint' type='revolute'>
        <pose relative_to='left_summit_base_footprint'>-0.2225 -0.2045 0.127 0 -0 0</pose>
        <parent>left_summit_base_footprint</parent>
        <child>left_summit_back_right_wheel_link</child>
        <axis>
          <xyz>0 1 0</xyz>
          <limit>
            <effort>100</effort>
            <velocity>100</velocity>
            <lower>-1e+16</lower>
            <upper>1e+16</upper>
          </limit>
          <dynamics>
            <spring_reference>0</spring_reference>
            <spring_stiffness>0</spring_stiffness>
          </dynamics>
        </axis>
      </joint>
      <link name='left_summit_back_right_wheel_link'>
        <pose relative_to='left_summit_back_right_wheel_joint'>0 0 0 0 -0 0</pose>
        <inertial>
          <pose>0 0 0 0 -0 0</pose>
          <mass>6.5</mass>
          <inertia>
            <ixx>0.0303095</ixx>
            <ixy>0</ixy>
            <ixz>0</ixz>
            <iyy>0.0524193</iyy>
            <iyz>0</iyz>
            <izz>0.0303095</izz>
          </inertia>
        </inertial>
        <collision name='left_summit_back_right_wheel_link_collision'>
          <pose>0 0 0 1.5708 -0 0</pose>
          <geometry>
            <cylinder>
              <length>0.087</length>
              <radius>0.127</radius>
            </cylinder>
          </geometry>
          <surface>
            <contact>
              <ode>
                <kp>1e+08</kp>
                <kd>1</kd>
                <min_depth>0.001</min_depth>
              </ode>
            </contact>
            <friction>
              <ode>
                <mu>0.9</mu>
                <mu2>0.9</mu2>
              </ode>
              <torsional>
                <ode/>
              </torsional>
            </friction>
            <bounce/>
          </surface>
          <max_contacts>10</max_contacts>
        </collision>
        <visual name='left_summit_back_right_wheel_link_visual'>
          <pose>0 0 0 0 -0 0</pose>
          <geometry>
            <mesh>
              <scale>1 1 1</scale>
              <uri>file:///ros2_ws/install/summit_xl_description/share/summit_xl_description/meshes/wheels/omni_wheel_2.dae</uri>
            </mesh>
          </geometry>
        </visual>
        <self_collide>0</self_collide>
        <enable_wind>0</enable_wind>
        <kinematic>0</kinematic>
      </link>
      <joint name='left_summit_front_left_wheel_joint' type='revolute'>
        <pose relative_to='left_summit_base_footprint'>0.2225 0.2045 0.127 0 -0 0</pose>
        <parent>left_summit_base_footprint</parent>
        <child>left_summit_front_left_wheel_link</child>
        <axis>
          <xyz>0 1 0</xyz>
          <limit>
            <effort>100</effort>
            <velocity>100</velocity>
            <lower>-1e+16</lower>
            <upper>1e+16</upper>
          </limit>
          <dynamics>
            <spring_reference>0</spring_reference>
            <spring_stiffness>0</spring_stiffness>
          </dynamics>
        </axis>
      </joint>
      <link name='left_summit_front_left_wheel_link'>
        <pose relative_to='left_summit_front_left_wheel_joint'>0 0 0 0 -0 0</pose>
        <inertial>
          <pose>0 0 0 0 -0 0</pose>
          <mass>6.5</mass>
          <inertia>
            <ixx>0.0303095</ixx>
            <ixy>0</ixy>
            <ixz>0</ixz>
            <iyy>0.0524193</iyy>
            <iyz>0</iyz>
            <izz>0.0303095</izz>
          </inertia>
        </inertial>
        <collision name='left_summit_front_left_wheel_link_collision'>
          <pose>0 0 0 1.5708 -0 0</pose>
          <geometry>
            <cylinder>
              <length>0.087</length>
              <radius>0.127</radius>
            </cylinder>
          </geometry>
          <surface>
            <contact>
              <ode>
                <kp>1e+08</kp>
                <kd>1</kd>
                <min_depth>0.001</min_depth>
              </ode>
            </contact>
            <friction>
              <ode>
                <mu>0.9</mu>
                <mu2>0.9</mu2>
              </ode>
              <torsional>
                <ode/>
              </torsional>
            </friction>
            <bounce/>
          </surface>
          <max_contacts>10</max_contacts>
        </collision>
        <visual name='left_summit_front_left_wheel_link_visual'>
          <pose>0 0 0 0 -0 0</pose>
          <geometry>
            <mesh>
              <scale>1 1 1</scale>
              <uri>file:///ros2_ws/install/summit_xl_description/share/summit_xl_description/meshes/wheels/omni_wheel_1.dae</uri>
            </mesh>
          </geometry>
        </visual>
        <self_collide>0</self_collide>
        <enable_wind>0</enable_wind>
        <kinematic>0</kinematic>
      </link>
      <joint name='left_summit_front_right_wheel_joint' type='revolute'>
        <pose relative_to='left_summit_base_footprint'>0.2225 -0.2045 0.127 0 0.2 0</pose>
        <parent>left_summit_base_footprint</parent>
        <child>left_summit_front_right_wheel_link</child>
        <axis>
          <xyz>0 1 0</xyz>
          <limit>
            <effort>100</effort>
            <velocity>100</velocity>
            <lower>-1e+16</lower>
            <upper>1e+16</upper>
          </limit>
          <dynamics>
            <spring_reference>0</spring_reference>
            <spring_stiffness>0</spring_stiffness>
          </dynamics>
        </axis>
      </joint>
      <link name='left_summit_front_right_wheel_link'>
        <pose relative_to='left_summit_front_right_wheel_joint'>0 0 0 0 -0 0</pose>
        <inertial>
          <pose>0 0 0 0 -0 0</pose>
          <mass>6.5</mass>
          <inertia>
            <ixx>0.0303095</ixx>
            <ixy>0</ixy>
            <ixz>0</ixz>
            <iyy>0.0524193</iyy>
            <iyz>0</iyz>
            <izz>0.0303095</izz>
          </inertia>
        </inertial>
        <collision name='left_summit_front_right_wheel_link_collision'>
          <pose>0 0 0 1.5708 -0 0</pose>
          <geometry>
            <cylinder>
              <length>0.087</length>
              <radius>0.127</radius>
            </cylinder>
          </geometry>
          <surface>
            <contact>
              <ode>
                <kp>1e+08</kp>
                <kd>1</kd>
                <min_depth>0.001</min_depth>
              </ode>
            </contact>
            <friction>
              <ode>
                <mu>0.9</mu>
                <mu2>0.9</mu2>
              </ode>
              <torsional>
                <ode/>
              </torsional>
            </friction>
            <bounce/>
          </surface>
          <max_contacts>10</max_contacts>
        </collision>
        <visual name='left_summit_front_right_wheel_link_visual'>
          <pose>0 0 0 0 -0 0</pose>
          <geometry>
            <mesh>
              <scale>1 1 1</scale>
              <uri>file:///ros2_ws/install/summit_xl_description/share/summit_xl_description/meshes/wheels/omni_wheel_2.dae</uri>
            </mesh>
          </geometry>
        </visual>
        <self_collide>0</self_collide>
        <enable_wind>0</enable_wind>
        <kinematic>0</kinematic>
      </link>
      <joint name='ur_left_shoulder_pan_joint' type='revolute'>
        <pose relative_to='left_summit_base_footprint'>0 0 0.7055 0 -0 1.57159</pose>
        <parent>left_summit_base_footprint</parent>
        <child>ur_left_shoulder_link</child>
        <axis>
          <xyz>0 0 1</xyz>
          <limit>
            <lower>-6.28319</lower>
            <upper>6.28319</upper>
            <effort>150</effort>
            <velocity>3.14159</velocity>
          </limit>
          <dynamics>
            <damping>0</damping>
            <friction>0</friction>
            <spring_reference>0</spring_reference>
            <spring_stiffness>0</spring_stiffness>
          </dynamics>
        </axis>
      </joint>
      <link name='ur_left_shoulder_link'>
        <pose relative_to='ur_left_shoulder_pan_joint'>0 0 0 0 -0 0</pose>
        <inertial>
          <pose>0 0 0 0 -0 0</pose>
          <mass>3.761</mass>
          <inertia>
            <ixx>0.0104368</ixx>
            <ixy>0</ixy>
            <ixz>0</ixz>
            <iyy>0.0104368</iyy>
            <iyz>0</iyz>
            <izz>0.0067698</izz>
          </inertia>
        </inertial>
        <collision name='ur_left_shoulder_link_collision'>
          <pose>0 0 0 0 -0 3.14159</pose>
          <geometry>
            <mesh>
              <scale>1 1 1</scale>
              <uri>file:///ros2_ws/install/ur_description/share/ur_description/meshes/ur5e/collision/shoulder.stl</uri>
            </mesh>
          </geometry>
          <surface>
            <contact>
              <ode/>
            </contact>
            <friction>
              <ode/>
              <torsional>
                <ode/>
              </torsional>
            </friction>
            <bounce/>
          </surface>
          <max_contacts>10</max_contacts>
        </collision>
        <visual name='ur_left_shoulder_link_visual'>
          <pose>0 0 0 0 -0 3.14159</pose>
          <geometry>
            <mesh>
              <scale>1 1 1</scale>
              <uri>file:///ros2_ws/install/ur_description/share/ur_description/meshes/ur5e/visual/shoulder.dae</uri>
            </mesh>
          </geometry>
        </visual>
        <gravity>0</gravity>
        <self_collide>0</self_collide>
        <enable_wind>0</enable_wind>
        <kinematic>0</kinematic>
      </link>
      <joint name='ur_left_shoulder_lift_joint' type='revolute'>
        <pose relative_to='ur_left_shoulder_link'>0 0 0 1.5708 -0 0</pose>
        <parent>ur_left_shoulder_link</parent>
        <child>ur_left_upper_arm_link</child>
        <axis>
          <xyz>0 0 1</xyz>
          <limit>
            <lower>-6.28319</lower>
            <upper>6.28319</upper>
            <effort>150</effort>
            <velocity>3.14159</velocity>
          </limit>
          <dynamics>
            <damping>0</damping>
            <friction>0</friction>
            <spring_reference>0</spring_reference>
            <spring_stiffness>0</spring_stiffness>
          </dynamics>
        </axis>
      </joint>
      <link name='ur_left_upper_arm_link'>
        <pose relative_to='ur_left_shoulder_lift_joint'>0 0 0 0 -0 0</pose>
        <inertial>
          <pose>-0.2125 0 0.138 3.14159 1.57079 3.14159</pose>
          <mass>8.058</mass>
          <inertia>
            <ixx>0.128542</ixx>
            <ixy>0</ixy>
            <ixz>0</ixz>
            <iyy>0.128542</iyy>
            <iyz>0</iyz>
            <izz>0.0145044</izz>
          </inertia>
        </inertial>
        <collision name='ur_left_upper_arm_link_collision'>
          <pose>0 0 0.138 1.5708 0 -1.5708</pose>
          <geometry>
            <mesh>
              <scale>1 1 1</scale>
              <uri>file:///ros2_ws/install/ur_description/share/ur_description/meshes/ur5e/collision/upperarm.stl</uri>
            </mesh>
          </geometry>
          <surface>
            <contact>
              <ode/>
            </contact>
            <friction>
              <ode/>
              <torsional>
                <ode/>
              </torsional>
            </friction>
            <bounce/>
          </surface>
          <max_contacts>10</max_contacts>
        </collision>
        <visual name='ur_left_upper_arm_link_visual'>
          <pose>0 0 0.138 1.5708 0 -1.5708</pose>
          <geometry>
            <mesh>
              <scale>1 1 1</scale>
              <uri>file:///ros2_ws/install/ur_description/share/ur_description/meshes/ur5e/visual/upperarm.dae</uri>
            </mesh>
          </geometry>
        </visual>
        <gravity>0</gravity>
        <self_collide>0</self_collide>
        <enable_wind>0</enable_wind>
        <kinematic>0</kinematic>
      </link>
      <joint name='ur_left_elbow_joint' type='revolute'>
        <pose relative_to='ur_left_upper_arm_link'>-0.425 0 0 0 -0 0</pose>
        <parent>ur_left_upper_arm_link</parent>
        <child>ur_left_forearm_link</child>
        <axis>
          <xyz>0 0 1</xyz>
          <limit>
            <lower>-3.14159</lower>
            <upper>3.14159</upper>
            <effort>150</effort>
            <velocity>3.14159</velocity>
          </limit>
          <dynamics>
            <damping>0</damping>
            <friction>0</friction>
            <spring_reference>0</spring_reference>
            <spring_stiffness>0</spring_stiffness>
          </dynamics>
        </axis>
      </joint>
      <link name='ur_left_forearm_link'>
        <pose relative_to='ur_left_elbow_joint'>0 0 0 0 -0 0</pose>
        <inertial>
          <pose>-0.1961 0 0.007 3.14159 1.57079 3.14159</pose>
          <mass>2.846</mass>
          <inertia>
            <ixx>0.0390426</ixx>
            <ixy>0</ixy>
            <ixz>0</ixz>
            <iyy>0.0390426</iyy>
            <iyz>0</iyz>
            <izz>0.0051228</izz>
          </inertia>
        </inertial>
        <collision name='ur_left_forearm_link_collision'>
          <pose>0 0 0.007 1.5708 0 -1.5708</pose>
          <geometry>
            <mesh>
              <scale>1 1 1</scale>
              <uri>file:///ros2_ws/install/ur_description/share/ur_description/meshes/ur5e/collision/forearm.stl</uri>
            </mesh>
          </geometry>
          <surface>
            <contact>
              <ode/>
            </contact>
            <friction>
              <ode/>
              <torsional>
                <ode/>
              </torsional>
            </friction>
            <bounce/>
          </surface>
          <max_contacts>10</max_contacts>
        </collision>
        <visual name='ur_left_forearm_link_visual'>
          <pose>0 0 0.007 1.5708 0 -1.5708</pose>
          <geometry>
            <mesh>
              <scale>1 1 1</scale>
              <uri>file:///ros2_ws/install/ur_description/share/ur_description/meshes/ur5e/visual/forearm.dae</uri>
            </mesh>
          </geometry>
        </visual>
        <gravity>0</gravity>
        <self_collide>0</self_collide>
        <enable_wind>0</enable_wind>
        <kinematic>0</kinematic>
      </link>
      <joint name='ur_left_wrist_1_joint' type='revolute'>
        <pose relative_to='ur_left_forearm_link'>-0.3922 0 0.1333 0 -0 0</pose>
        <parent>ur_left_forearm_link</parent>
        <child>ur_left_wrist_1_link</child>
        <axis>
          <xyz>0 0 1</xyz>
          <limit>
            <lower>-6.28319</lower>
            <upper>6.28319</upper>
            <effort>28</effort>
            <velocity>3.14159</velocity>
          </limit>
          <dynamics>
            <damping>0</damping>
            <friction>0</friction>
            <spring_reference>0</spring_reference>
            <spring_stiffness>0</spring_stiffness>
          </dynamics>
        </axis>
      </joint>
      <link name='ur_left_wrist_1_link'>
        <pose relative_to='ur_left_wrist_1_joint'>0 0 0 0 -0 0</pose>
        <inertial>
          <pose>0 0 0 0 -0 0</pose>
          <mass>1.37</mass>
          <inertia>
            <ixx>0.002877</ixx>
            <ixy>0</ixy>
            <ixz>0</ixz>
            <iyy>0.002877</iyy>
            <iyz>0</iyz>
            <izz>0.002466</izz>
          </inertia>
        </inertial>
        <collision name='ur_left_wrist_1_link_collision'>
          <pose>0 0 -0.127 1.5708 -0 0</pose>
          <geometry>
            <mesh>
              <scale>1 1 1</scale>
              <uri>file:///ros2_ws/install/ur_description/share/ur_description/meshes/ur5e/collision/wrist1.stl</uri>
            </mesh>
          </geometry>
          <surface>
            <contact>
              <ode/>
            </contact>
            <friction>
              <ode/>
              <torsional>
                <ode/>
              </torsional>
            </friction>
            <bounce/>
          </surface>
          <max_contacts>10</max_contacts>
        </collision>
        <visual name='ur_left_wrist_1_link_visual'>
          <pose>0 0 -0.127 1.5708 -0 0</pose>
          <geometry>
            <mesh>
              <scale>1 1 1</scale>
              <uri>file:///ros2_ws/install/ur_description/share/ur_description/meshes/ur5e/visual/wrist1.dae</uri>
            </mesh>
          </geometry>
        </visual>
        <gravity>0</gravity>
        <self_collide>0</self_collide>
        <enable_wind>0</enable_wind>
        <kinematic>0</kinematic>
      </link>
      <joint name='ur_left_wrist_2_joint' type='revolute'>
        <pose relative_to='ur_left_wrist_1_link'>0 -0.0997 -0 1.5708 -0 0</pose>
        <parent>ur_left_wrist_1_link</parent>
        <child>ur_left_wrist_2_link</child>
        <axis>
          <xyz>0 0 1</xyz>
          <limit>
            <lower>-6.28319</lower>
            <upper>6.28319</upper>
            <effort>28</effort>
            <velocity>3.14159</velocity>
          </limit>
          <dynamics>
            <damping>0</damping>
            <friction>0</friction>
            <spring_reference>0</spring_reference>
            <spring_stiffness>0</spring_stiffness>
          </dynamics>
        </axis>
      </joint>
      <link name='ur_left_wrist_2_link'>
        <pose relative_to='ur_left_wrist_2_joint'>0 0 0 0 -0 0</pose>
        <inertial>
          <pose>0 0 0 0 -0 0</pose>
          <mass>1.3</mass>
          <inertia>
            <ixx>0.00273</ixx>
            <ixy>0</ixy>
            <ixz>0</ixz>
            <iyy>0.00273</iyy>
            <iyz>0</iyz>
            <izz>0.00234</izz>
          </inertia>
        </inertial>
        <collision name='ur_left_wrist_2_link_collision'>
          <pose>0 0 -0.0997 0 -0 0</pose>
          <geometry>
            <mesh>
              <scale>1 1 1</scale>
              <uri>file:///ros2_ws/install/ur_description/share/ur_description/meshes/ur5e/collision/wrist2.stl</uri>
            </mesh>
          </geometry>
          <surface>
            <contact>
              <ode/>
            </contact>
            <friction>
              <ode/>
              <torsional>
                <ode/>
              </torsional>
            </friction>
            <bounce/>
          </surface>
          <max_contacts>10</max_contacts>
        </collision>
        <visual name='ur_left_wrist_2_link_visual'>
          <pose>0 0 -0.0997 0 -0 0</pose>
          <geometry>
            <mesh>
              <scale>1 1 1</scale>
              <uri>file:///ros2_ws/install/ur_description/share/ur_description/meshes/ur5e/visual/wrist2.dae</uri>
            </mesh>
          </geometry>
        </visual>
        <gravity>0</gravity>
        <self_collide>0</self_collide>
        <enable_wind>0</enable_wind>
        <kinematic>0</kinematic>
      </link>
      <joint name='ur_left_wrist_3_joint' type='revolute'>
        <pose relative_to='ur_left_wrist_2_link'>0 0.0996 -0 -1.5708 0 0</pose>
        <parent>ur_left_wrist_2_link</parent>
        <child>ur_left_wrist_3_link</child>
        <axis>
          <xyz>0 0 1</xyz>
          <limit>
            <lower>-6.28319</lower>
            <upper>6.28319</upper>
            <effort>28</effort>
            <velocity>3.14159</velocity>
          </limit>
          <dynamics>
            <damping>0</damping>
            <friction>0</friction>
            <spring_reference>0</spring_reference>
            <spring_stiffness>0</spring_stiffness>
          </dynamics>
        </axis>
      </joint>
      <link name='ur_left_wrist_3_link'>
        <pose relative_to='ur_left_wrist_3_joint'>0 0 0 0 -0 0</pose>
        <inertial>
          <pose>0.022996 4.7e-05 -0.001147 0 -0 0</pose>
          <mass>0.768993</mass>
          <inertia>
            <ixx>0.003931</ixx>
            <ixy>5.77379e-05</ixy>
            <ixz>-2.96646e-05</ixz>
            <iyy>0.00422799</iyy>
            <iyz>4.27705e-06</iyz>
            <izz>0.00243413</izz>
          </inertia>
        </inertial>
        <collision name='ur_left_wrist_3_link_collision'>
          <pose>0 0 -0.0989 1.5708 -0 0</pose>
          <geometry>
            <mesh>
              <scale>1 1 1</scale>
              <uri>file:///ros2_ws/install/ur_description/share/ur_description/meshes/ur5e/collision/wrist3.stl</uri>
            </mesh>
          </geometry>
          <surface>
            <contact>
              <ode/>
            </contact>
            <friction>
              <ode/>
              <torsional>
                <ode/>
              </torsional>
            </friction>
            <bounce/>
          </surface>
          <max_contacts>10</max_contacts>
        </collision>
        <collision name='ur_left_wrist_3_link_fixed_joint_lump__ur_left_robotiq_hand_collision_1'>
          <pose>0 0 0 -3e-06 -1.57079 3.14159</pose>
          <geometry>
            <mesh>
              <scale>1 1 1</scale>
              <uri>file:///ros2_ws/install/robotiq_hand_e/share/robotiq_hand_e/meshes/wiring_gripper.stl</uri>
            </mesh>
          </geometry>
          <max_contacts>10</max_contacts>
          <surface>
            <contact>
              <ode/>
            </contact>
            <bounce/>
            <friction>
              <torsional>
                <ode/>
              </torsional>
              <ode/>
            </friction>
          </surface>
        </collision>
        <collision name='ur_left_wrist_3_link_fixed_joint_lump__ur_left_finger_left_collision_2'>
          <pose>-0.02609 0.014 0.113279 1.57159 0.000798 -1.57239</pose>
          <geometry>
            <mesh>
              <scale>1 1 1</scale>
              <uri>file:///ros2_ws/install/robotiq_hand_e/share/robotiq_hand_e/meshes/hand_e_finger_left_.stl</uri>
            </mesh>
          </geometry>
          <max_contacts>10</max_contacts>
          <surface>
            <contact>
              <ode/>
            </contact>
            <bounce/>
            <friction>
              <torsional>
                <ode/>
              </torsional>
              <ode/>
            </friction>
          </surface>
        </collision>
        <collision name='ur_left_wrist_3_link_fixed_joint_lump__ur_left_finger_right_collision_3'>
          <pose>0.025864 -0.014583 0.113298 1.57159 0.000798 -1.57239</pose>
          <geometry>
            <mesh>
              <scale>1 1 1</scale>
              <uri>file:///ros2_ws/install/robotiq_hand_e/share/robotiq_hand_e/meshes/hand_e_finger_right_.stl</uri>
            </mesh>
          </geometry>
          <max_contacts>10</max_contacts>
          <surface>
            <contact>
              <ode/>
            </contact>
            <bounce/>
            <friction>
              <torsional>
                <ode/>
              </torsional>
              <ode/>
            </friction>
          </surface>
        </collision>
        <visual name='ur_left_wrist_3_link_visual'>
          <pose>0 0 -0.0989 1.5708 -0 0</pose>
          <geometry>
            <mesh>
              <scale>1 1 1</scale>
              <uri>file:///ros2_ws/install/ur_description/share/ur_description/meshes/ur5e/visual/wrist3.dae</uri>
            </mesh>
          </geometry>
        </visual>
        <visual name='ur_left_wrist_3_link_fixed_joint_lump__ur_left_robotiq_hand_visual_1'>
          <pose>0 0 0 -3e-06 -1.57079 3.14159</pose>
          <geometry>
            <mesh>
              <scale>1 1 1</scale>
              <uri>file:///ros2_ws/install/robotiq_hand_e/share/robotiq_hand_e/meshes/wiring_gripper.stl</uri>
            </mesh>
          </geometry>
        </visual>
        <visual name='ur_left_wrist_3_link_fixed_joint_lump__ur_left_finger_left_visual_2'>
          <pose>-0.02609 0.014 0.113279 1.57159 0.000798 -1.57239</pose>
          <geometry>
            <mesh>
              <scale>1 1 1</scale>
              <uri>file:///ros2_ws/install/robotiq_hand_e/share/robotiq_hand_e/meshes/hand_e_finger_left_.stl</uri>
            </mesh>
          </geometry>
        </visual>
        <visual name='ur_left_wrist_3_link_fixed_joint_lump__ur_left_finger_right_visual_3'>
          <pose>0.025864 -0.014583 0.113298 1.57159 0.000798 -1.57239</pose>
          <geometry>
            <mesh>
              <scale>1 1 1</scale>
              <uri>file:///ros2_ws/install/robotiq_hand_e/share/robotiq_hand_e/meshes/hand_e_finger_right_.stl</uri>
            </mesh>
          </geometry>
        </visual>
        <gravity>0</gravity>
        <self_collide>0</self_collide>
        <enable_wind>0</enable_wind>
        <kinematic>0</kinematic>
      </link>
      <plugin name='ros_control' filename='libgazebo_ros_control.so'>
        <robotParam>robot_description</robotParam>
        <controlPeriod>0.001</controlPeriod>
        <robotSimType>gazebo_ros_control/DefaultRobotHWSim</robotSimType>
        <legacyModeNS>1</legacyModeNS>
      </plugin>
      <plugin name='omni_steering' filename='libgazebo_ros_planar_move.so'>
        <namespace>left_summit</namespace>
        <command_topic>left_summit/cmd_vel</command_topic>
        <odometry_topic>left_summit/odom</odometry_topic>
        <odometry_frame>left_summit_odom</odometry_frame>
        <odometryRate>50.0</odometryRate>
        <robot_base_frame>left_summit_base_footprint</robot_base_frame>
        <publish_odom>1</publish_odom>
        <publish_odom_tf>1</publish_odom_tf>
        <enableYAxis>1</enableYAxis>
      </plugin>
      <static>0</static>
      <plugin name='left_gazebo_ros2_control' filename='libgazebo_ros2_control.so'>
        <parameters>/ros2_ws/install/ur/share/ur/config/left_controller.yaml</parameters>
        <ros>
          <namespace>left</namespace>
        </ros>
      </plugin>
      <pose>-0.66 0 0 0 -0 0</pose>
    </model>
    <model name='right_robot'>
      <link name='right_summit_base_footprint'>
        <inertial>
          <pose>5e-06 -5e-06 0.14373 0 -0 0</pose>
          <mass>131.405</mass>
          <inertia>
            <ixx>2.28126</ixx>
            <ixy>0.147666</ixy>
            <ixz>-0.000130347</ixz>
            <iyy>7.83548</iyy>
            <iyz>0.000132399</iyz>
            <izz>6.43846</izz>
          </inertia>
        </inertial>
        <collision name='right_summit_base_footprint_fixed_joint_lump__right_summit_base_link_collision'>
          <pose>0 0 0.127 0 -0 0</pose>
          <geometry>
            <mesh>
              <scale>1 1 1</scale>
              <uri>file:///ros2_ws/install/summit_xl_description/share/summit_xl_description/meshes/bases/xls/summit_xls_chassis.dae</uri>
            </mesh>
          </geometry>
          <surface>
            <contact>
              <ode/>
            </contact>
            <friction>
              <ode/>
              <torsional>
                <ode/>
              </torsional>
            </friction>
            <bounce/>
          </surface>
          <max_contacts>10</max_contacts>
        </collision>
        <collision name='right_summit_base_footprint_fixed_joint_lump__right_summit_front_laser_base_link_collision_1'>
          <pose>0.2865 -0.20894 0.4243 3.14159 -0 -0.785398</pose>
          <geometry>
            <mesh>
              <scale>1 1 1</scale>
              <uri>model://robotnik_sensors/meshes/sick_s300.dae</uri>
            </mesh>
          </geometry>
          <max_contacts>10</max_contacts>
          <surface>
            <contact>
              <ode/>
            </contact>
            <bounce/>
            <friction>
              <torsional>
                <ode/>
              </torsional>
              <ode/>
            </friction>
          </surface>
        </collision>
        <collision name='right_summit_base_footprint_fixed_joint_lump__right_summit_rear_laser_base_link_collision_2'>
          <pose>-0.2865 0.20894 0.4243 3.14159 -0 2.35619</pose>
          <geometry>
            <mesh>
              <scale>1 1 1</scale>
              <uri>model://robotnik_sensors/meshes/sick_s300.dae</uri>
            </mesh>
          </geometry>
          <max_contacts>10</max_contacts>
          <surface>
            <contact>
              <ode/>
            </contact>
            <bounce/>
            <friction>
              <torsional>
                <ode/>
              </torsional>
              <ode/>
            </friction>
          </surface>
        </collision>
        <collision name='right_summit_base_footprint_fixed_joint_lump__ur_right_base_link_inertia_collision_3'>
          <pose>0 0 0.543 0 -0 1.57</pose>
          <geometry>
            <mesh>
              <scale>1 1 1</scale>
              <uri>file:///ros2_ws/install/ur_description/share/ur_description/meshes/ur5e/collision/base.stl</uri>
            </mesh>
          </geometry>
          <max_contacts>10</max_contacts>
          <surface>
            <contact>
              <ode/>
            </contact>
            <bounce/>
            <friction>
              <torsional>
                <ode/>
              </torsional>
              <ode/>
            </friction>
          </surface>
        </collision>
        <visual name='right_summit_base_footprint_visual'>
          <pose>0 0 0.5 0 -0 0</pose>
          <geometry>
            <box>
              <size>0.001 0.001 0.001</size>
            </box>
          </geometry>
        </visual>
        <visual name='right_summit_base_footprint_fixed_joint_lump__right_summit_base_link_visual_1'>
          <pose>0 0 0.127 0 -0 0</pose>
          <geometry>
            <mesh>
              <scale>1 1 1</scale>
              <uri>file:///ros2_ws/install/summit_xl_description/share/summit_xl_description/meshes/bases/xls/summit_xls_chassis.stl</uri>
            </mesh>
          </geometry>
          <material>
            <script>
              <name>Gazebo/Black</name>
              <uri>file://media/materials/scripts/gazebo.material</uri>
            </script>
          </material>
        </visual>
        <visual name='right_summit_base_footprint_fixed_joint_lump__right_summit_base_logo_front_visual_2'>
          <pose>0.345 0 0.127 0 0 -1.5708</pose>
          <geometry>
            <mesh>
              <scale>1 1 1</scale>
              <uri>file:///ros2_ws/install/summit_xl_description/share/summit_xl_description/meshes/bases/xls/robotnik_logo_chasis.stl</uri>
            </mesh>
          </geometry>
        </visual>
        <visual name='right_summit_base_footprint_fixed_joint_lump__right_summit_base_logo_left_visual_3'>
          <pose>0 0.28931 0.41762 0 -0 0</pose>
          <geometry>
            <mesh>
              <scale>1 1 1</scale>
              <uri>file:///ros2_ws/install/summit_xl_description/share/summit_xl_description/meshes/bases/xls/robotnik_logo_chasis.stl</uri>
            </mesh>
          </geometry>
        </visual>
        <visual name='right_summit_base_footprint_fixed_joint_lump__right_summit_base_logo_rear_visual_4'>
          <pose>-0.345 0 0.127 0 -0 1.5708</pose>
          <geometry>
            <mesh>
              <scale>1 1 1</scale>
              <uri>file:///ros2_ws/install/summit_xl_description/share/summit_xl_description/meshes/bases/xls/robotnik_logo_chasis.stl</uri>
            </mesh>
          </geometry>
        </visual>
        <visual name='right_summit_base_footprint_fixed_joint_lump__right_summit_base_logo_right_visual_5'>
          <pose>0 -0.28931 0.41762 0 -0 3.14159</pose>
          <geometry>
            <mesh>
              <scale>1 1 1</scale>
              <uri>file:///ros2_ws/install/summit_xl_description/share/summit_xl_description/meshes/bases/xls/robotnik_logo_chasis.stl</uri>
            </mesh>
          </geometry>
        </visual>
        <visual name='right_summit_base_footprint_fixed_joint_lump__right_summit_base_chapa_visual_6'>
          <pose>0 0 0.50762 0 -0 0</pose>
          <geometry>
            <mesh>
              <scale>1 1 1</scale>
              <uri>file:///ros2_ws/install/summit_xl_description/share/summit_xl_description/meshes/bases/xls/summit_xls_chapas_inox_tapas.stl</uri>
            </mesh>
          </geometry>
        </visual>
        <visual name='right_summit_base_footprint_fixed_joint_lump__right_summit_front_laser_base_link_visual_7'>
          <pose>0.2865 -0.20894 0.4243 1.5708 -0 -0.785398</pose>
          <geometry>
            <mesh>
              <scale>1 1 1</scale>
              <uri>model://robotnik_sensors/meshes/sick_s300_color.dae</uri>
            </mesh>
          </geometry>
        </visual>
        <visual name='right_summit_base_footprint_fixed_joint_lump__right_summit_imu_link_visual_8'>
          <pose>0.127 -0.129 0.339 0 -0 0</pose>
          <geometry>
            <box>
              <size>0.001 0.001 0.001</size>
            </box>
          </geometry>
        </visual>
        <visual name='right_summit_base_footprint_fixed_joint_lump__right_summit_rear_laser_base_link_visual_9'>
          <pose>-0.2865 0.20894 0.4243 1.5708 -0 2.35619</pose>
          <geometry>
            <mesh>
              <scale>1 1 1</scale>
              <uri>model://robotnik_sensors/meshes/sick_s300_color.dae</uri>
            </mesh>
          </geometry>
        </visual>
        <visual name='right_summit_base_footprint_fixed_joint_lump__ur_right_base_link_inertia_visual_10'>
          <pose>0 0 0.543 0 -0 1.57</pose>
          <geometry>
            <mesh>
              <scale>1 1 1</scale>
              <uri>file:///ros2_ws/install/ur_description/share/ur_description/meshes/ur5e/visual/base.dae</uri>
            </mesh>
          </geometry>
        </visual>
        <gravity>0</gravity>
        <sensor name='right_summit_front_laser_sensor' type='ray'>
          <visualize>0</visualize>
          <update_rate>12.5</update_rate>
          <ray>
            <scan>
              <horizontal>
                <samples>541</samples>
                <resolution>1</resolution>
                <min_angle>-2.3562</min_angle>
                <max_angle>2.3562</max_angle>
              </horizontal>
              <vertical>
                <samples>1</samples>
                <min_angle>0</min_angle>
                <max_angle>0</max_angle>
              </vertical>
            </scan>
            <range>
              <min>0.1</min>
              <max>30</max>
              <resolution>0.03</resolution>
            </range>
            <noise>
              <type>gaussian</type>
              <mean>0</mean>
              <stddev>0.03</stddev>
            </noise>
          </ray>
          <plugin name='right_summit_front_laser_controller' filename='libgazebo_ros_ray_sensor.so'>
            <ros>
              <remapping>~/out:=front_laser/scan</remapping>
            </ros>
            <frame_name>right_summit_front_laser_link</frame_name>
            <output_type>sensor_msgs/LaserScan</output_type>
          </plugin>
          <pose>0.2865 -0.20894 0.3083 3.14159 -0 -0.785398</pose>
        </sensor>
        <gravity>1</gravity>
        <sensor name='right_summit_imu_imu_sensor' type='imu'>
          <always_on>1</always_on>
          <update_rate>100</update_rate>
          <visualize>1</visualize>
          <topic>__default_topic__</topic>
          <plugin name='right_summit_imu_imu_plugin' filename='libgazebo_ros_imu_sensor.so'>
            <topicName>imu/data</topicName>
            <bodyName>right_summit_imu_link</bodyName>
            <updateRateHZ>100.0</updateRateHZ>
            <gaussianNoise>0.0</gaussianNoise>
            <xyzOffset>0 0 0</xyzOffset>
            <rpyOffset>0 0 0</rpyOffset>
            <frameName>right_summit_imu_link</frameName>
          </plugin>
          <pose>0.127 -0.129 0.339 0 -0 0</pose>
          <imu/>
        </sensor>
        <sensor name='right_summit_rear_laser_sensor' type='ray'>
          <visualize>0</visualize>
          <update_rate>12.5</update_rate>
          <ray>
            <scan>
              <horizontal>
                <samples>541</samples>
                <resolution>1</resolution>
                <min_angle>-2.3562</min_angle>
                <max_angle>2.3562</max_angle>
              </horizontal>
              <vertical>
                <samples>1</samples>
                <min_angle>0</min_angle>
                <max_angle>0</max_angle>
              </vertical>
            </scan>
            <range>
              <min>0.1</min>
              <max>30</max>
              <resolution>0.03</resolution>
            </range>
            <noise>
              <type>gaussian</type>
              <mean>0</mean>
              <stddev>0.03</stddev>
            </noise>
          </ray>
          <plugin name='right_summit_rear_laser_controller' filename='libgazebo_ros_ray_sensor.so'>
            <ros>
              <remapping>~/out:=rear_laser/scan</remapping>
            </ros>
            <frame_name>right_summit_rear_laser_link</frame_name>
            <output_type>sensor_msgs/LaserScan</output_type>
          </plugin>
          <pose>-0.2865 0.20894 0.3083 3.14159 -0 2.35619</pose>
        </sensor>
        <self_collide>0</self_collide>
        <enable_wind>0</enable_wind>
        <kinematic>0</kinematic>
      </link>
      <joint name='right_summit_back_left_wheel_joint' type='revolute'>
        <pose relative_to='right_summit_base_footprint'>-0.2225 0.2045 0.127 0 -0 0</pose>
        <parent>right_summit_base_footprint</parent>
        <child>right_summit_back_left_wheel_link</child>
        <axis>
          <xyz>0 1 0</xyz>
          <limit>
            <effort>100</effort>
            <velocity>100</velocity>
            <lower>-1e+16</lower>
            <upper>1e+16</upper>
          </limit>
          <dynamics>
            <spring_reference>0</spring_reference>
            <spring_stiffness>0</spring_stiffness>
          </dynamics>
        </axis>
      </joint>
      <link name='right_summit_back_left_wheel_link'>
        <pose relative_to='right_summit_back_left_wheel_joint'>0 0 0 0 -0 0</pose>
        <inertial>
          <pose>0 0 0 0 -0 0</pose>
          <mass>6.5</mass>
          <inertia>
            <ixx>0.0303095</ixx>
            <ixy>0</ixy>
            <ixz>0</ixz>
            <iyy>0.0524193</iyy>
            <iyz>0</iyz>
            <izz>0.0303095</izz>
          </inertia>
        </inertial>
        <collision name='right_summit_back_left_wheel_link_collision'>
          <pose>0 0 0 1.5708 -0 0</pose>
          <geometry>
            <cylinder>
              <length>0.087</length>
              <radius>0.127</radius>
            </cylinder>
          </geometry>
          <surface>
            <contact>
              <ode>
                <kp>1e+08</kp>
                <kd>1</kd>
                <min_depth>0.001</min_depth>
              </ode>
            </contact>
            <friction>
              <ode>
                <mu>0.9</mu>
                <mu2>0.9</mu2>
              </ode>
              <torsional>
                <ode/>
              </torsional>
            </friction>
            <bounce/>
          </surface>
          <max_contacts>10</max_contacts>
        </collision>
        <visual name='right_summit_back_left_wheel_link_visual'>
          <pose>0 0 0 0 -0 0</pose>
          <geometry>
            <mesh>
              <scale>1 1 1</scale>
              <uri>file:///ros2_ws/install/summit_xl_description/share/summit_xl_description/meshes/wheels/omni_wheel_1.dae</uri>
            </mesh>
          </geometry>
        </visual>
        <self_collide>0</self_collide>
        <enable_wind>0</enable_wind>
        <kinematic>0</kinematic>
      </link>
      <joint name='right_summit_back_right_wheel_joint' type='revolute'>
        <pose relative_to='right_summit_base_footprint'>-0.2225 -0.2045 0.127 0 -0 0</pose>
        <parent>right_summit_base_footprint</parent>
        <child>right_summit_back_right_wheel_link</child>
        <axis>
          <xyz>0 1 0</xyz>
          <limit>
            <effort>100</effort>
            <velocity>100</velocity>
            <lower>-1e+16</lower>
            <upper>1e+16</upper>
          </limit>
          <dynamics>
            <spring_reference>0</spring_reference>
            <spring_stiffness>0</spring_stiffness>
          </dynamics>
        </axis>
      </joint>
      <link name='right_summit_back_right_wheel_link'>
        <pose relative_to='right_summit_back_right_wheel_joint'>0 0 0 0 -0 0</pose>
        <inertial>
          <pose>0 0 0 0 -0 0</pose>
          <mass>6.5</mass>
          <inertia>
            <ixx>0.0303095</ixx>
            <ixy>0</ixy>
            <ixz>0</ixz>
            <iyy>0.0524193</iyy>
            <iyz>0</iyz>
            <izz>0.0303095</izz>
          </inertia>
        </inertial>
        <collision name='right_summit_back_right_wheel_link_collision'>
          <pose>0 0 0 1.5708 -0 0</pose>
          <geometry>
            <cylinder>
              <length>0.087</length>
              <radius>0.127</radius>
            </cylinder>
          </geometry>
          <surface>
            <contact>
              <ode>
                <kp>1e+08</kp>
                <kd>1</kd>
                <min_depth>0.001</min_depth>
              </ode>
            </contact>
            <friction>
              <ode>
                <mu>0.9</mu>
                <mu2>0.9</mu2>
              </ode>
              <torsional>
                <ode/>
              </torsional>
            </friction>
            <bounce/>
          </surface>
          <max_contacts>10</max_contacts>
        </collision>
        <visual name='right_summit_back_right_wheel_link_visual'>
          <pose>0 0 0 0 -0 0</pose>
          <geometry>
            <mesh>
              <scale>1 1 1</scale>
              <uri>file:///ros2_ws/install/summit_xl_description/share/summit_xl_description/meshes/wheels/omni_wheel_2.dae</uri>
            </mesh>
          </geometry>
        </visual>
        <self_collide>0</self_collide>
        <enable_wind>0</enable_wind>
        <kinematic>0</kinematic>
      </link>
      <joint name='right_summit_front_left_wheel_joint' type='revolute'>
        <pose relative_to='right_summit_base_footprint'>0.2225 0.2045 0.127 0 -0 0</pose>
        <parent>right_summit_base_footprint</parent>
        <child>right_summit_front_left_wheel_link</child>
        <axis>
          <xyz>0 1 0</xyz>
          <limit>
            <effort>100</effort>
            <velocity>100</velocity>
            <lower>-1e+16</lower>
            <upper>1e+16</upper>
          </limit>
          <dynamics>
            <spring_reference>0</spring_reference>
            <spring_stiffness>0</spring_stiffness>
          </dynamics>
        </axis>
      </joint>
      <link name='right_summit_front_left_wheel_link'>
        <pose relative_to='right_summit_front_left_wheel_joint'>0 0 0 0 -0 0</pose>
        <inertial>
          <pose>0 0 0 0 -0 0</pose>
          <mass>6.5</mass>
          <inertia>
            <ixx>0.0303095</ixx>
            <ixy>0</ixy>
            <ixz>0</ixz>
            <iyy>0.0524193</iyy>
            <iyz>0</iyz>
            <izz>0.0303095</izz>
          </inertia>
        </inertial>
        <collision name='right_summit_front_left_wheel_link_collision'>
          <pose>0 0 0 1.5708 -0 0</pose>
          <geometry>
            <cylinder>
              <length>0.087</length>
              <radius>0.127</radius>
            </cylinder>
          </geometry>
          <surface>
            <contact>
              <ode>
                <kp>1e+08</kp>
                <kd>1</kd>
                <min_depth>0.001</min_depth>
              </ode>
            </contact>
            <friction>
              <ode>
                <mu>0.9</mu>
                <mu2>0.9</mu2>
              </ode>
              <torsional>
                <ode/>
              </torsional>
            </friction>
            <bounce/>
          </surface>
          <max_contacts>10</max_contacts>
        </collision>
        <visual name='right_summit_front_left_wheel_link_visual'>
          <pose>0 0 0 0 -0 0</pose>
          <geometry>
            <mesh>
              <scale>1 1 1</scale>
              <uri>file:///ros2_ws/install/summit_xl_description/share/summit_xl_description/meshes/wheels/omni_wheel_1.dae</uri>
            </mesh>
          </geometry>
        </visual>
        <self_collide>0</self_collide>
        <enable_wind>0</enable_wind>
        <kinematic>0</kinematic>
      </link>
      <joint name='right_summit_front_right_wheel_joint' type='revolute'>
        <pose relative_to='right_summit_base_footprint'>0.2225 -0.2045 0.127 0 0.2 0</pose>
        <parent>right_summit_base_footprint</parent>
        <child>right_summit_front_right_wheel_link</child>
        <axis>
          <xyz>0 1 0</xyz>
          <limit>
            <effort>100</effort>
            <velocity>100</velocity>
            <lower>-1e+16</lower>
            <upper>1e+16</upper>
          </limit>
          <dynamics>
            <spring_reference>0</spring_reference>
            <spring_stiffness>0</spring_stiffness>
          </dynamics>
        </axis>
      </joint>
      <link name='right_summit_front_right_wheel_link'>
        <pose relative_to='right_summit_front_right_wheel_joint'>0 0 0 0 -0 0</pose>
        <inertial>
          <pose>0 0 0 0 -0 0</pose>
          <mass>6.5</mass>
          <inertia>
            <ixx>0.0303095</ixx>
            <ixy>0</ixy>
            <ixz>0</ixz>
            <iyy>0.0524193</iyy>
            <iyz>0</iyz>
            <izz>0.0303095</izz>
          </inertia>
        </inertial>
        <collision name='right_summit_front_right_wheel_link_collision'>
          <pose>0 0 0 1.5708 -0 0</pose>
          <geometry>
            <cylinder>
              <length>0.087</length>
              <radius>0.127</radius>
            </cylinder>
          </geometry>
          <surface>
            <contact>
              <ode>
                <kp>1e+08</kp>
                <kd>1</kd>
                <min_depth>0.001</min_depth>
              </ode>
            </contact>
            <friction>
              <ode>
                <mu>0.9</mu>
                <mu2>0.9</mu2>
              </ode>
              <torsional>
                <ode/>
              </torsional>
            </friction>
            <bounce/>
          </surface>
          <max_contacts>10</max_contacts>
        </collision>
        <visual name='right_summit_front_right_wheel_link_visual'>
          <pose>0 0 0 0 -0 0</pose>
          <geometry>
            <mesh>
              <scale>1 1 1</scale>
              <uri>file:///ros2_ws/install/summit_xl_description/share/summit_xl_description/meshes/wheels/omni_wheel_2.dae</uri>
            </mesh>
          </geometry>
        </visual>
        <self_collide>0</self_collide>
        <enable_wind>0</enable_wind>
        <kinematic>0</kinematic>
      </link>
      <joint name='ur_right_shoulder_pan_joint' type='revolute'>
        <pose relative_to='right_summit_base_footprint'>0 0 0.7055 0 0 -1.57159</pose>
        <parent>right_summit_base_footprint</parent>
        <child>ur_right_shoulder_link</child>
        <axis>
          <xyz>0 0 1</xyz>
          <limit>
            <lower>-6.28319</lower>
            <upper>6.28319</upper>
            <effort>150</effort>
            <velocity>3.14159</velocity>
          </limit>
          <dynamics>
            <damping>0</damping>
            <friction>0</friction>
            <spring_reference>0</spring_reference>
            <spring_stiffness>0</spring_stiffness>
          </dynamics>
        </axis>
      </joint>
      <link name='ur_right_shoulder_link'>
        <pose relative_to='ur_right_shoulder_pan_joint'>0 0 0 0 -0 0</pose>
        <inertial>
          <pose>0 0 0 0 -0 0</pose>
          <mass>3.761</mass>
          <inertia>
            <ixx>0.0104368</ixx>
            <ixy>0</ixy>
            <ixz>0</ixz>
            <iyy>0.0104368</iyy>
            <iyz>0</iyz>
            <izz>0.0067698</izz>
          </inertia>
        </inertial>
        <collision name='ur_right_shoulder_link_collision'>
          <pose>0 0 0 0 -0 3.14159</pose>
          <geometry>
            <mesh>
              <scale>1 1 1</scale>
              <uri>file:///ros2_ws/install/ur_description/share/ur_description/meshes/ur5e/collision/shoulder.stl</uri>
            </mesh>
          </geometry>
          <surface>
            <contact>
              <ode/>
            </contact>
            <friction>
              <ode/>
              <torsional>
                <ode/>
              </torsional>
            </friction>
            <bounce/>
          </surface>
          <max_contacts>10</max_contacts>
        </collision>
        <visual name='ur_right_shoulder_link_visual'>
          <pose>0 0 0 0 -0 3.14159</pose>
          <geometry>
            <mesh>
              <scale>1 1 1</scale>
              <uri>file:///ros2_ws/install/ur_description/share/ur_description/meshes/ur5e/visual/shoulder.dae</uri>
            </mesh>
          </geometry>
        </visual>
        <gravity>0</gravity>
        <self_collide>0</self_collide>
        <enable_wind>0</enable_wind>
        <kinematic>0</kinematic>
      </link>
      <joint name='ur_right_shoulder_lift_joint' type='revolute'>
        <pose relative_to='ur_right_shoulder_link'>0 0 0 1.5708 -0 0</pose>
        <parent>ur_right_shoulder_link</parent>
        <child>ur_right_upper_arm_link</child>
        <axis>
          <xyz>0 0 1</xyz>
          <limit>
            <lower>-6.28319</lower>
            <upper>6.28319</upper>
            <effort>150</effort>
            <velocity>3.14159</velocity>
          </limit>
          <dynamics>
            <damping>0</damping>
            <friction>0</friction>
            <spring_reference>0</spring_reference>
            <spring_stiffness>0</spring_stiffness>
          </dynamics>
        </axis>
      </joint>
      <link name='ur_right_upper_arm_link'>
        <pose relative_to='ur_right_shoulder_lift_joint'>0 0 0 0 -0 0</pose>
        <inertial>
          <pose>-0.2125 0 0.138 3.14159 1.57079 3.14159</pose>
          <mass>8.058</mass>
          <inertia>
            <ixx>0.128542</ixx>
            <ixy>0</ixy>
            <ixz>0</ixz>
            <iyy>0.128542</iyy>
            <iyz>0</iyz>
            <izz>0.0145044</izz>
          </inertia>
        </inertial>
        <collision name='ur_right_upper_arm_link_collision'>
          <pose>0 0 0.138 1.5708 0 -1.5708</pose>
          <geometry>
            <mesh>
              <scale>1 1 1</scale>
              <uri>file:///ros2_ws/install/ur_description/share/ur_description/meshes/ur5e/collision/upperarm.stl</uri>
            </mesh>
          </geometry>
          <surface>
            <contact>
              <ode/>
            </contact>
            <friction>
              <ode/>
              <torsional>
                <ode/>
              </torsional>
            </friction>
            <bounce/>
          </surface>
          <max_contacts>10</max_contacts>
        </collision>
        <visual name='ur_right_upper_arm_link_visual'>
          <pose>0 0 0.138 1.5708 0 -1.5708</pose>
          <geometry>
            <mesh>
              <scale>1 1 1</scale>
              <uri>file:///ros2_ws/install/ur_description/share/ur_description/meshes/ur5e/visual/upperarm.dae</uri>
            </mesh>
          </geometry>
        </visual>
        <gravity>0</gravity>
        <self_collide>0</self_collide>
        <enable_wind>0</enable_wind>
        <kinematic>0</kinematic>
      </link>
      <joint name='ur_right_elbow_joint' type='revolute'>
        <pose relative_to='ur_right_upper_arm_link'>-0.425 0 0 0 -0 0</pose>
        <parent>ur_right_upper_arm_link</parent>
        <child>ur_right_forearm_link</child>
        <axis>
          <xyz>0 0 1</xyz>
          <limit>
            <lower>-3.14159</lower>
            <upper>3.14159</upper>
            <effort>150</effort>
            <velocity>3.14159</velocity>
          </limit>
          <dynamics>
            <damping>0</damping>
            <friction>0</friction>
            <spring_reference>0</spring_reference>
            <spring_stiffness>0</spring_stiffness>
          </dynamics>
        </axis>
      </joint>
      <link name='ur_right_forearm_link'>
        <pose relative_to='ur_right_elbow_joint'>0 0 0 0 -0 0</pose>
        <inertial>
          <pose>-0.1961 0 0.007 3.14159 1.57079 3.14159</pose>
          <mass>2.846</mass>
          <inertia>
            <ixx>0.0390426</ixx>
            <ixy>0</ixy>
            <ixz>0</ixz>
            <iyy>0.0390426</iyy>
            <iyz>0</iyz>
            <izz>0.0051228</izz>
          </inertia>
        </inertial>
        <collision name='ur_right_forearm_link_collision'>
          <pose>0 0 0.007 1.5708 0 -1.5708</pose>
          <geometry>
            <mesh>
              <scale>1 1 1</scale>
              <uri>file:///ros2_ws/install/ur_description/share/ur_description/meshes/ur5e/collision/forearm.stl</uri>
            </mesh>
          </geometry>
          <surface>
            <contact>
              <ode/>
            </contact>
            <friction>
              <ode/>
              <torsional>
                <ode/>
              </torsional>
            </friction>
            <bounce/>
          </surface>
          <max_contacts>10</max_contacts>
        </collision>
        <visual name='ur_right_forearm_link_visual'>
          <pose>0 0 0.007 1.5708 0 -1.5708</pose>
          <geometry>
            <mesh>
              <scale>1 1 1</scale>
              <uri>file:///ros2_ws/install/ur_description/share/ur_description/meshes/ur5e/visual/forearm.dae</uri>
            </mesh>
          </geometry>
        </visual>
        <gravity>0</gravity>
        <self_collide>0</self_collide>
        <enable_wind>0</enable_wind>
        <kinematic>0</kinematic>
      </link>
      <joint name='ur_right_wrist_1_joint' type='revolute'>
        <pose relative_to='ur_right_forearm_link'>-0.3922 0 0.1333 0 -0 0</pose>
        <parent>ur_right_forearm_link</parent>
        <child>ur_right_wrist_1_link</child>
        <axis>
          <xyz>0 0 1</xyz>
          <limit>
            <lower>-6.28319</lower>
            <upper>6.28319</upper>
            <effort>28</effort>
            <velocity>3.14159</velocity>
          </limit>
          <dynamics>
            <damping>0</damping>
            <friction>0</friction>
            <spring_reference>0</spring_reference>
            <spring_stiffness>0</spring_stiffness>
          </dynamics>
        </axis>
      </joint>
      <link name='ur_right_wrist_1_link'>
        <pose relative_to='ur_right_wrist_1_joint'>0 0 0 0 -0 0</pose>
        <inertial>
          <pose>0 0 0 0 -0 0</pose>
          <mass>1.37</mass>
          <inertia>
            <ixx>0.002877</ixx>
            <ixy>0</ixy>
            <ixz>0</ixz>
            <iyy>0.002877</iyy>
            <iyz>0</iyz>
            <izz>0.002466</izz>
          </inertia>
        </inertial>
        <collision name='ur_right_wrist_1_link_collision'>
          <pose>0 0 -0.127 1.5708 -0 0</pose>
          <geometry>
            <mesh>
              <scale>1 1 1</scale>
              <uri>file:///ros2_ws/install/ur_description/share/ur_description/meshes/ur5e/collision/wrist1.stl</uri>
            </mesh>
          </geometry>
          <surface>
            <contact>
              <ode/>
            </contact>
            <friction>
              <ode/>
              <torsional>
                <ode/>
              </torsional>
            </friction>
            <bounce/>
          </surface>
          <max_contacts>10</max_contacts>
        </collision>
        <visual name='ur_right_wrist_1_link_visual'>
          <pose>0 0 -0.127 1.5708 -0 0</pose>
          <geometry>
            <mesh>
              <scale>1 1 1</scale>
              <uri>file:///ros2_ws/install/ur_description/share/ur_description/meshes/ur5e/visual/wrist1.dae</uri>
            </mesh>
          </geometry>
        </visual>
        <gravity>0</gravity>
        <self_collide>0</self_collide>
        <enable_wind>0</enable_wind>
        <kinematic>0</kinematic>
      </link>
      <joint name='ur_right_wrist_2_joint' type='revolute'>
        <pose relative_to='ur_right_wrist_1_link'>0 -0.0997 -0 1.5708 -0 0</pose>
        <parent>ur_right_wrist_1_link</parent>
        <child>ur_right_wrist_2_link</child>
        <axis>
          <xyz>0 0 1</xyz>
          <limit>
            <lower>-6.28319</lower>
            <upper>6.28319</upper>
            <effort>28</effort>
            <velocity>3.14159</velocity>
          </limit>
          <dynamics>
            <damping>0</damping>
            <friction>0</friction>
            <spring_reference>0</spring_reference>
            <spring_stiffness>0</spring_stiffness>
          </dynamics>
        </axis>
      </joint>
      <link name='ur_right_wrist_2_link'>
        <pose relative_to='ur_right_wrist_2_joint'>0 0 0 0 -0 0</pose>
        <inertial>
          <pose>0 0 0 0 -0 0</pose>
          <mass>1.3</mass>
          <inertia>
            <ixx>0.00273</ixx>
            <ixy>0</ixy>
            <ixz>0</ixz>
            <iyy>0.00273</iyy>
            <iyz>0</iyz>
            <izz>0.00234</izz>
          </inertia>
        </inertial>
        <collision name='ur_right_wrist_2_link_collision'>
          <pose>0 0 -0.0997 0 -0 0</pose>
          <geometry>
            <mesh>
              <scale>1 1 1</scale>
              <uri>file:///ros2_ws/install/ur_description/share/ur_description/meshes/ur5e/collision/wrist2.stl</uri>
            </mesh>
          </geometry>
          <surface>
            <contact>
              <ode/>
            </contact>
            <friction>
              <ode/>
              <torsional>
                <ode/>
              </torsional>
            </friction>
            <bounce/>
          </surface>
          <max_contacts>10</max_contacts>
        </collision>
        <visual name='ur_right_wrist_2_link_visual'>
          <pose>0 0 -0.0997 0 -0 0</pose>
          <geometry>
            <mesh>
              <scale>1 1 1</scale>
              <uri>file:///ros2_ws/install/ur_description/share/ur_description/meshes/ur5e/visual/wrist2.dae</uri>
            </mesh>
          </geometry>
        </visual>
        <gravity>0</gravity>
        <self_collide>0</self_collide>
        <enable_wind>0</enable_wind>
        <kinematic>0</kinematic>
      </link>
      <joint name='ur_right_wrist_3_joint' type='revolute'>
        <pose relative_to='ur_right_wrist_2_link'>0 0.0996 -0 -1.5708 0 0</pose>
        <parent>ur_right_wrist_2_link</parent>
        <child>ur_right_wrist_3_link</child>
        <axis>
          <xyz>0 0 1</xyz>
          <limit>
            <lower>-6.28319</lower>
            <upper>6.28319</upper>
            <effort>28</effort>
            <velocity>3.14159</velocity>
          </limit>
          <dynamics>
            <damping>0</damping>
            <friction>0</friction>
            <spring_reference>0</spring_reference>
            <spring_stiffness>0</spring_stiffness>
          </dynamics>
        </axis>
      </joint>
      <link name='ur_right_wrist_3_link'>
        <pose relative_to='ur_right_wrist_3_joint'>0 0 0 0 -0 0</pose>
        <inertial>
          <pose>0.022996 4.7e-05 -0.001147 0 -0 0</pose>
          <mass>0.768993</mass>
          <inertia>
            <ixx>0.003931</ixx>
            <ixy>5.77379e-05</ixy>
            <ixz>-2.96646e-05</ixz>
            <iyy>0.00422799</iyy>
            <iyz>4.27705e-06</iyz>
            <izz>0.00243413</izz>
          </inertia>
        </inertial>
        <collision name='ur_right_wrist_3_link_collision'>
          <pose>0 0 -0.0989 1.5708 -0 0</pose>
          <geometry>
            <mesh>
              <scale>1 1 1</scale>
              <uri>file:///ros2_ws/install/ur_description/share/ur_description/meshes/ur5e/collision/wrist3.stl</uri>
            </mesh>
          </geometry>
          <surface>
            <contact>
              <ode/>
            </contact>
            <friction>
              <ode/>
              <torsional>
                <ode/>
              </torsional>
            </friction>
            <bounce/>
          </surface>
          <max_contacts>10</max_contacts>
        </collision>
        <collision name='ur_right_wrist_3_link_fixed_joint_lump__ur_right_robotiq_hand_collision_1'>
          <pose>0 0 0 -3e-06 -1.57079 3.14159</pose>
          <geometry>
            <mesh>
              <scale>1 1 1</scale>
              <uri>file:///ros2_ws/install/robotiq_hand_e/share/robotiq_hand_e/meshes/wiring_gripper.stl</uri>
            </mesh>
          </geometry>
          <max_contacts>10</max_contacts>
          <surface>
            <contact>
              <ode/>
            </contact>
            <bounce/>
            <friction>
              <torsional>
                <ode/>
              </torsional>
              <ode/>
            </friction>
          </surface>
        </collision>
        <collision name='ur_right_wrist_3_link_fixed_joint_lump__ur_right_finger_left_collision_2'>
          <pose>-0.02609 0.014 0.113279 1.57159 0.000798 -1.57239</pose>
          <geometry>
            <mesh>
              <scale>1 1 1</scale>
              <uri>file:///ros2_ws/install/robotiq_hand_e/share/robotiq_hand_e/meshes/hand_e_finger_left_.stl</uri>
            </mesh>
          </geometry>
          <max_contacts>10</max_contacts>
          <surface>
            <contact>
              <ode/>
            </contact>
            <bounce/>
            <friction>
              <torsional>
                <ode/>
              </torsional>
              <ode/>
            </friction>
          </surface>
        </collision>
        <collision name='ur_right_wrist_3_link_fixed_joint_lump__ur_right_finger_right_collision_3'>
          <pose>0.025864 -0.014583 0.113298 1.57159 0.000798 -1.57239</pose>
          <geometry>
            <mesh>
              <scale>1 1 1</scale>
              <uri>file:///ros2_ws/install/robotiq_hand_e/share/robotiq_hand_e/meshes/hand_e_finger_right_.stl</uri>
            </mesh>
          </geometry>
          <max_contacts>10</max_contacts>
          <surface>
            <contact>
              <ode/>
            </contact>
            <bounce/>
            <friction>
              <torsional>
                <ode/>
              </torsional>
              <ode/>
            </friction>
          </surface>
        </collision>
        <visual name='ur_right_wrist_3_link_visual'>
          <pose>0 0 -0.0989 1.5708 -0 0</pose>
          <geometry>
            <mesh>
              <scale>1 1 1</scale>
              <uri>file:///ros2_ws/install/ur_description/share/ur_description/meshes/ur5e/visual/wrist3.dae</uri>
            </mesh>
          </geometry>
        </visual>
        <visual name='ur_right_wrist_3_link_fixed_joint_lump__ur_right_robotiq_hand_visual_1'>
          <pose>0 0 0 -3e-06 -1.57079 3.14159</pose>
          <geometry>
            <mesh>
              <scale>1 1 1</scale>
              <uri>file:///ros2_ws/install/robotiq_hand_e/share/robotiq_hand_e/meshes/wiring_gripper.stl</uri>
            </mesh>
          </geometry>
        </visual>
        <visual name='ur_right_wrist_3_link_fixed_joint_lump__ur_right_finger_left_visual_2'>
          <pose>-0.02609 0.014 0.113279 1.57159 0.000798 -1.57239</pose>
          <geometry>
            <mesh>
              <scale>1 1 1</scale>
              <uri>file:///ros2_ws/install/robotiq_hand_e/share/robotiq_hand_e/meshes/hand_e_finger_left_.stl</uri>
            </mesh>
          </geometry>
        </visual>
        <visual name='ur_right_wrist_3_link_fixed_joint_lump__ur_right_finger_right_visual_3'>
          <pose>0.025864 -0.014583 0.113298 1.57159 0.000798 -1.57239</pose>
          <geometry>
            <mesh>
              <scale>1 1 1</scale>
              <uri>file:///ros2_ws/install/robotiq_hand_e/share/robotiq_hand_e/meshes/hand_e_finger_right_.stl</uri>
            </mesh>
          </geometry>
        </visual>
        <gravity>0</gravity>
        <self_collide>0</self_collide>
        <enable_wind>0</enable_wind>
        <kinematic>0</kinematic>
      </link>
      <plugin name='ros_control' filename='libgazebo_ros_control.so'>
        <robotParam>robot_description</robotParam>
        <controlPeriod>0.001</controlPeriod>
        <robotSimType>gazebo_ros_control/DefaultRobotHWSim</robotSimType>
        <legacyModeNS>1</legacyModeNS>
      </plugin>
      <plugin name='omni_steering' filename='libgazebo_ros_planar_move.so'>
        <namespace>right_summit</namespace>
        <command_topic>right_summit/cmd_vel</command_topic>
        <odometry_topic>right_summit/odom</odometry_topic>
        <odometry_frame>right_summit_odom</odometry_frame>
        <odometryRate>50.0</odometryRate>
        <robot_base_frame>right_summit_base_footprint</robot_base_frame>
        <publish_odom>1</publish_odom>
        <publish_odom_tf>1</publish_odom_tf>
        <enableYAxis>1</enableYAxis>
      </plugin>
      <static>0</static>
      <plugin name='right_gazebo_ros2_control' filename='libgazebo_ros2_control.so'>
        <parameters>/ros2_ws/install/ur/share/ur/config/right_controller.yaml</parameters>
        <ros>
          <namespace>right</namespace>
        </ros>
      </plugin>
      <pose>0.66 0 0 0 -0 0</pose>
    </model>
    <model name='camera'>
      <pose>0.152642 0.862981 0.05 0 -0 0</pose>
      <link name='link'>
        <inertial>
          <mass>0.1</mass>
          <inertia>
            <ixx>0.000166667</ixx>
            <iyy>0.000166667</iyy>
            <izz>0.000166667</izz>
            <ixy>0</ixy>
            <ixz>0</ixz>
            <iyz>0</iyz>
          </inertia>
          <pose>0 0 0 0 -0 0</pose>
        </inertial>
        <collision name='collision'>
          <geometry>
            <box>
              <size>0.1 0.1 0.1</size>
            </box>
          </geometry>
          <max_contacts>10</max_contacts>
          <surface>
            <contact>
              <ode/>
            </contact>
            <bounce/>
            <friction>
              <torsional>
                <ode/>
              </torsional>
              <ode/>
            </friction>
          </surface>
        </collision>
        <visual name='visual'>
          <geometry>
            <box>
              <size>0.1 0.1 0.1</size>
            </box>
          </geometry>
        </visual>
        <sensor name='camera' type='camera'>
          <camera>
            <horizontal_fov>1.047</horizontal_fov>
            <image>
              <width>320</width>
              <height>240</height>
            </image>
            <clip>
              <near>0.1</near>
              <far>100</far>
            </clip>
          </camera>
          <always_on>1</always_on>
          <update_rate>30</update_rate>
          <visualize>1</visualize>
        </sensor>
        <self_collide>0</self_collide>
        <enable_wind>0</enable_wind>
        <kinematic>0</kinematic>
      </link>
    </model>
  </world>
</sdf>
