<?xml version="1.0" ?><!-- =================================================================================== --><!-- |    This document was autogenerated by xacro from /home/lar/ros2/official_ws/src/base/xacro/base_spawn.urdf.xacro | --><!-- |    EDITING THIS FILE BY HAND IS NOT RECOMMENDED                                 | --><!-- =================================================================================== --><robot name="base"><!-- ***************** --><!-- Imported elements --><!-- ***************** --><!-- First we import all posible elements defined in the urdf.xacro files. All these elements are defined as macro:xacros --><gazebo reference="base_footprint"><material>Gazebo/Green</material></gazebo><!-- in kg--><!-- source en.wikipedia.org/wiki/List_of_moments_of_inertia--><!-- This file unifies all sensors that can be used on simulation, defined as xacro:macros --><!-- Includes --><gazebo><plugin filename="libgazebo_ros_control.so" name="ros_control"><robotParam>robot_description</robotParam><controlPeriod>0.001</controlPeriod><robotSimType>gazebo_ros_control/DefaultRobotHWSim</robotSimType><legacyModeNS>true</legacyModeNS></plugin></gazebo><!-- <link name="$(arg parent_base)"/>
    <link name="$(arg namespace)_prismatic_1"/>
    <link name="$(arg namespace)_prismatic_2"/>
    <link name="$(arg namespace)_revolute"/> --><!-- *************** --><!-- Robots Elements --><!-- *************** --><!-- Here we create the robot elements using the xacro:macros imported at the beggining of this file --><link name="right_summit_base_footprint"><visual><origin rpy="0 0 0" xyz="0 0 0.5"/><geometry><box size="0.001 0.001 0.001"/></geometry></visual></link><joint name="right_summit_base_footprint_joint" type="fixed"><origin rpy="0 0 0" xyz="0 0 0.127"/><!-- ${wheel_radius} property must be defined inside wheel description --><parent link="right_summit_base_footprint"/><child link="right_summit_base_link"/></joint><!-- <gazebo reference="${prefix}base_footprint">
      <ode>
        <solver>
          <type>quick</type>
          <iters>0</iters>
          <sor>1.0</sor>
        </solver>
      </ode>
    </gazebo> --><!-- BASE_LINK --><link name="right_summit_base_link"><inertial><mass value="125.0"/><origin xyz="0 0 0"/><inertia ixx="1.391" ixy="0.004" ixz="0.0" iyy="6.853" iyz="0.0" izz="6.125"/></inertial><visual><origin rpy="0 0 0" xyz="0 0 0"/><geometry><mesh filename="file:///home/lar/ros2/official_ws/install/summit_xl_description/share/summit_xl_description/meshes/bases/xls/summit_xls_chassis.stl"/></geometry><material name="black"><color rgba="0.0 0.0 0.0 1"/></material></visual><collision><origin rpy="0 0 0 " xyz="0 0 0"/><geometry><mesh filename="file:///home/lar/ros2/official_ws/install/summit_xl_description/share/summit_xl_description/meshes/bases/xls/summit_xls_chassis.dae"/></geometry></collision></link><gazebo reference="right_summit_base_link"><material>Gazebo/Black</material></gazebo><!-- CHAPAS INOX TAPAS --><link name="right_summit_base_chapa"><visual><origin rpy="0 0 0" xyz="0 0 0"/><geometry><mesh filename="file:///home/lar/ros2/official_ws/install/summit_xl_description/share/summit_xl_description/meshes/bases/xls/summit_xls_chapas_inox_tapas.stl"/></geometry><material name="darkgrey"><color rgba="0.5 0.5 0.5 1"/></material></visual></link><joint name="right_summit_base_tapa_joint" type="fixed"><origin rpy="0 0 0" xyz="0.0 0 0.38062"/><parent link="right_summit_base_link"/><child link="right_summit_base_chapa"/></joint><!-- LOGO ROBOTNIK IZQUIERDO --><link name="right_summit_base_logo_left"><visual><origin rpy="0 0 0" xyz="0 0 0"/><geometry><mesh filename="file:///home/lar/ros2/official_ws/install/summit_xl_description/share/summit_xl_description/meshes/bases/xls/robotnik_logo_chasis.stl"/></geometry><material name="darkgrey"><color rgba="0.5 0.5 0.5 1"/></material></visual></link><joint name="right_summit_base_logo_left_joint" type="fixed"><origin rpy="0 0 0" xyz="0.0 0.28931 0.29062"/><parent link="right_summit_base_link"/><child link="right_summit_base_logo_left"/></joint><!-- LOGO ROBOTNIK DERECHO --><link name="right_summit_base_logo_right"><visual><origin rpy="0 0 0" xyz="0 0 0"/><geometry><mesh filename="file:///home/lar/ros2/official_ws/install/summit_xl_description/share/summit_xl_description/meshes/bases/xls/robotnik_logo_chasis.stl"/></geometry><material name="darkgrey"><color rgba="0.5 0.5 0.5 1"/></material></visual></link><joint name="right_summit_base_logo_right_joint" type="fixed"><origin rpy="0 0 3.141592653589793" xyz="0.0 -0.28931 0.29062"/><parent link="right_summit_base_link"/><child link="right_summit_base_logo_right"/></joint><!-- LOGO ROBOTNIK FRONTAL --><link name="right_summit_base_logo_front"><visual><origin rpy="0 0 0" xyz="0 0 0"/><geometry><mesh filename="file:///home/lar/ros2/official_ws/install/summit_xl_description/share/summit_xl_description/meshes/bases/xls/robotnik_logo_chasis.stl"/></geometry><material name="darkgrey"><color rgba="0.5 0.5 0.5 1"/></material></visual></link><joint name="right_summit_base_logo_front_joint" type="fixed"><origin rpy="0 0 -1.5707963267948966" xyz="0.345 0.0 0.0"/><parent link="right_summit_base_link"/><child link="right_summit_base_logo_front"/></joint><!-- LOGO ROBOTNIK TRASERO --><link name="right_summit_base_logo_rear"><visual><origin rpy="0 0 0" xyz="0 0 0"/><geometry><mesh filename="file:///home/lar/ros2/official_ws/install/summit_xl_description/share/summit_xl_description/meshes/bases/xls/robotnik_logo_chasis.stl"/></geometry><material name="darkgrey"><color rgba="0.5 0.5 0.5 1"/></material></visual></link><joint name="right_summit_base_logo_rear_joint" type="fixed"><origin rpy="0 0 1.5707963267948966" xyz="-0.345 0.0 0.0"/><parent link="right_summit_base_link"/><child link="right_summit_base_logo_rear"/></joint><!-- DOCKING CONTACT --><link name="right_summit_base_docking_contact">
    </link><joint name="right_summit_base_docking_joint" type="fixed"><origin rpy="0 0 0" xyz="0.35 0 0.09"/><parent link="right_summit_base_link"/><child link="right_summit_base_docking_contact"/></joint><joint name="right_summit_front_right_wheel_joint" type="continuous"><parent link="right_summit_base_link"/><child link="right_summit_front_right_wheel_link"/><origin rpy="0 0 0" xyz="0.2225 -0.2045 0.0"/><axis rpy="0 0 0" xyz="0 1 0"/><limit effort="100" velocity="100"/><joint_properties damping="0.0" friction="0.0"/></joint><link name="right_summit_front_right_wheel_link"><visual><origin rpy="0 0 0" xyz="0 0 0"/><geometry><mesh filename="file:///home/lar/ros2/official_ws/install/summit_xl_description/share/summit_xl_description/meshes/wheels/omni_wheel_2.dae"/></geometry><material name="darkgrey"><color rgba="0.2 0.2 0.2 1"/></material></visual><collision><origin rpy="1.5707963267948966 0 0" xyz="0 0 0"/><geometry><!--sphere radius="${omni_wheel_radius}" /--><!--
          <xacro:if value="${reflect}">
              <mesh filename="file://$(find summit_xl_description)/meshes/wheels/omni_wheel_1.dae" />
          </xacro:if>
          <xacro:unless value="${reflect}">
              <mesh filename="file://$(find summit_xl_description)/meshes/wheels/omni_wheel_2.dae" />
					</xacro:unless>
--><cylinder length="0.087" radius="0.127"/><!-- sphere radius="${omni_wheel_radius}"/--></geometry></collision><inertial><mass value="6.5"/><origin xyz="0 0 0"/><inertia ixx="0.0303095" ixy="0" ixz="0" iyy="0.05241925" iyz="0" izz="0.0303095"/></inertial></link><!-- Transmission is important to link the joints and the controller (see summit_xl_control/config/summit_xl_control.yaml)--><transmission name="right_summit_front_right_wheel_joint_trans"><type>transmission_interface/SimpleTransmission</type><joint name="right_summit_front_right_wheel_joint"><hardwareInterface>hardware_interface/VelocityJointInterface</hardwareInterface></joint><actuator name="right_summit_front_right_wheel_joint_motor"><mechanicalReduction>1</mechanicalReduction></actuator></transmission><!-- <gazebo reference="${prefix}_wheel_link">
		<mu1 value="0.0"/>
		<mu2 value="0.0"/>
		<kp value="10000000.0" />
		<kd value="1.0" />
		<fdir1 value="1 0 0"/>
        <turnGravityOff>false</turnGravityOff>
    </gazebo> --><gazebo reference="right_summit_front_right_wheel_link"><mu1>0.9</mu1><mu2>0.9</mu2><minDepth>0.001</minDepth><kp>100000000</kp><kd>1</kd></gazebo><gazebo reference="right_summit_front_right_wheel_link"><implicitSpringDamper>true</implicitSpringDamper></gazebo><joint name="right_summit_front_left_wheel_joint" type="continuous"><parent link="right_summit_base_link"/><child link="right_summit_front_left_wheel_link"/><origin rpy="0 0 0" xyz="0.2225 0.2045 0.0"/><axis rpy="0 0 0" xyz="0 1 0"/><limit effort="100" velocity="100"/><joint_properties damping="0.0" friction="0.0"/></joint><link name="right_summit_front_left_wheel_link"><visual><origin rpy="0 0 0" xyz="0 0 0"/><geometry><mesh filename="file:///home/lar/ros2/official_ws/install/summit_xl_description/share/summit_xl_description/meshes/wheels/omni_wheel_1.dae"/></geometry><material name="darkgrey"><color rgba="0.2 0.2 0.2 1"/></material></visual><collision><origin rpy="1.5707963267948966 0 0" xyz="0 0 0"/><geometry><!--sphere radius="${omni_wheel_radius}" /--><!--
          <xacro:if value="${reflect}">
              <mesh filename="file://$(find summit_xl_description)/meshes/wheels/omni_wheel_1.dae" />
          </xacro:if>
          <xacro:unless value="${reflect}">
              <mesh filename="file://$(find summit_xl_description)/meshes/wheels/omni_wheel_2.dae" />
					</xacro:unless>
--><cylinder length="0.087" radius="0.127"/><!-- sphere radius="${omni_wheel_radius}"/--></geometry></collision><inertial><mass value="6.5"/><origin xyz="0 0 0"/><inertia ixx="0.0303095" ixy="0" ixz="0" iyy="0.05241925" iyz="0" izz="0.0303095"/></inertial></link><!-- Transmission is important to link the joints and the controller (see summit_xl_control/config/summit_xl_control.yaml)--><transmission name="right_summit_front_left_wheel_joint_trans"><type>transmission_interface/SimpleTransmission</type><joint name="right_summit_front_left_wheel_joint"><hardwareInterface>hardware_interface/VelocityJointInterface</hardwareInterface></joint><actuator name="right_summit_front_left_wheel_joint_motor"><mechanicalReduction>1</mechanicalReduction></actuator></transmission><!-- <gazebo reference="${prefix}_wheel_link">
		<mu1 value="0.0"/>
		<mu2 value="0.0"/>
		<kp value="10000000.0" />
		<kd value="1.0" />
		<fdir1 value="1 0 0"/>
        <turnGravityOff>false</turnGravityOff>
    </gazebo> --><gazebo reference="right_summit_front_left_wheel_link"><mu1>0.9</mu1><mu2>0.9</mu2><minDepth>0.001</minDepth><kp>100000000</kp><kd>1</kd></gazebo><gazebo reference="right_summit_front_left_wheel_link"><implicitSpringDamper>true</implicitSpringDamper></gazebo><joint name="right_summit_back_left_wheel_joint" type="continuous"><parent link="right_summit_base_link"/><child link="right_summit_back_left_wheel_link"/><origin rpy="0 0 0" xyz="-0.2225 0.2045 0.0"/><axis rpy="0 0 0" xyz="0 1 0"/><limit effort="100" velocity="100"/><joint_properties damping="0.0" friction="0.0"/></joint><link name="right_summit_back_left_wheel_link"><visual><origin rpy="0 0 0" xyz="0 0 0"/><geometry><mesh filename="file:///home/lar/ros2/official_ws/install/summit_xl_description/share/summit_xl_description/meshes/wheels/omni_wheel_1.dae"/></geometry><material name="darkgrey"><color rgba="0.2 0.2 0.2 1"/></material></visual><collision><origin rpy="1.5707963267948966 0 0" xyz="0 0 0"/><geometry><!--sphere radius="${omni_wheel_radius}" /--><!--
          <xacro:if value="${reflect}">
              <mesh filename="file://$(find summit_xl_description)/meshes/wheels/omni_wheel_1.dae" />
          </xacro:if>
          <xacro:unless value="${reflect}">
              <mesh filename="file://$(find summit_xl_description)/meshes/wheels/omni_wheel_2.dae" />
					</xacro:unless>
--><cylinder length="0.087" radius="0.127"/><!-- sphere radius="${omni_wheel_radius}"/--></geometry></collision><inertial><mass value="6.5"/><origin xyz="0 0 0"/><inertia ixx="0.0303095" ixy="0" ixz="0" iyy="0.05241925" iyz="0" izz="0.0303095"/></inertial></link><!-- Transmission is important to link the joints and the controller (see summit_xl_control/config/summit_xl_control.yaml)--><transmission name="right_summit_back_left_wheel_joint_trans"><type>transmission_interface/SimpleTransmission</type><joint name="right_summit_back_left_wheel_joint"><hardwareInterface>hardware_interface/VelocityJointInterface</hardwareInterface></joint><actuator name="right_summit_back_left_wheel_joint_motor"><mechanicalReduction>1</mechanicalReduction></actuator></transmission><!-- <gazebo reference="${prefix}_wheel_link">
		<mu1 value="0.0"/>
		<mu2 value="0.0"/>
		<kp value="10000000.0" />
		<kd value="1.0" />
		<fdir1 value="1 0 0"/>
        <turnGravityOff>false</turnGravityOff>
    </gazebo> --><gazebo reference="right_summit_back_left_wheel_link"><mu1>0.9</mu1><mu2>0.9</mu2><minDepth>0.001</minDepth><kp>100000000</kp><kd>1</kd></gazebo><gazebo reference="right_summit_back_left_wheel_link"><implicitSpringDamper>true</implicitSpringDamper></gazebo><joint name="right_summit_back_right_wheel_joint" type="continuous"><parent link="right_summit_base_link"/><child link="right_summit_back_right_wheel_link"/><origin rpy="0 0 0" xyz="-0.2225 -0.2045 0.0"/><axis rpy="0 0 0" xyz="0 1 0"/><limit effort="100" velocity="100"/><joint_properties damping="0.0" friction="0.0"/></joint><link name="right_summit_back_right_wheel_link"><visual><origin rpy="0 0 0" xyz="0 0 0"/><geometry><mesh filename="file:///home/lar/ros2/official_ws/install/summit_xl_description/share/summit_xl_description/meshes/wheels/omni_wheel_2.dae"/></geometry><material name="darkgrey"><color rgba="0.2 0.2 0.2 1"/></material></visual><collision><origin rpy="1.5707963267948966 0 0" xyz="0 0 0"/><geometry><!--sphere radius="${omni_wheel_radius}" /--><!--
          <xacro:if value="${reflect}">
              <mesh filename="file://$(find summit_xl_description)/meshes/wheels/omni_wheel_1.dae" />
          </xacro:if>
          <xacro:unless value="${reflect}">
              <mesh filename="file://$(find summit_xl_description)/meshes/wheels/omni_wheel_2.dae" />
					</xacro:unless>
--><cylinder length="0.087" radius="0.127"/><!-- sphere radius="${omni_wheel_radius}"/--></geometry></collision><inertial><mass value="6.5"/><origin xyz="0 0 0"/><inertia ixx="0.0303095" ixy="0" ixz="0" iyy="0.05241925" iyz="0" izz="0.0303095"/></inertial></link><!-- Transmission is important to link the joints and the controller (see summit_xl_control/config/summit_xl_control.yaml)--><transmission name="right_summit_back_right_wheel_joint_trans"><type>transmission_interface/SimpleTransmission</type><joint name="right_summit_back_right_wheel_joint"><hardwareInterface>hardware_interface/VelocityJointInterface</hardwareInterface></joint><actuator name="right_summit_back_right_wheel_joint_motor"><mechanicalReduction>1</mechanicalReduction></actuator></transmission><!-- <gazebo reference="${prefix}_wheel_link">
		<mu1 value="0.0"/>
		<mu2 value="0.0"/>
		<kp value="10000000.0" />
		<kd value="1.0" />
		<fdir1 value="1 0 0"/>
        <turnGravityOff>false</turnGravityOff>
    </gazebo> --><gazebo reference="right_summit_back_right_wheel_link"><mu1>0.9</mu1><mu2>0.9</mu2><minDepth>0.001</minDepth><kp>100000000</kp><kd>1</kd></gazebo><gazebo reference="right_summit_back_right_wheel_link"><implicitSpringDamper>true</implicitSpringDamper></gazebo><joint name="right_summit_imu_joint" type="fixed"><axis xyz="1 0 0"/><!--origin xyz="0 0 0.2825"/--><origin rpy="0 0 0" xyz="0.127 -0.129 0.212"/><parent link="right_summit_base_link"/><child link="right_summit_imu_link"/></joint><link name="right_summit_imu_link"><inertial><origin rpy="0 0 0" xyz="0.0 0 0.01"/><mass value="0.005"/><inertia ixx="8.333333333333334e-10" ixy="0" ixz="0" iyy="8.333333333333334e-10" iyz="0" izz="8.333333333333334e-10"/></inertial><visual><origin rpy="0 0 0" xyz="0 0 0"/><geometry><box size="0.001 0.001 0.001"/></geometry></visual><!--collision>
	        <origin rpy="0 0 0" xyz="0 0 0"/>
	        <geometry>
	          <box size="0.001 0.001 0.001"/>
	        </geometry>
	      </collision--></link><!--<gazebo>--><!--<plugin name="${prefix}_controller" filename="libgazebo_ros_imu.so">--><!--<topicName>${ns}imu/data</topicName>--><!--<serviceName>imu/service</serviceName>--><!--<bodyName>${prefix}_link</bodyName>--><!--<updateRateHZ>50.0</updateRateHZ>--><!--<gaussianNoise>0.0</gaussianNoise>--><!--</plugin>--><!--</gazebo>--><gazebo reference="right_summit_imu_link"><gravity>true</gravity><sensor name="right_summit_imu_imu_sensor" type="imu"><always_on>true</always_on><update_rate>100</update_rate><visualize>true</visualize><topic>__default_topic__</topic><plugin filename="libgazebo_ros_imu_sensor.so" name="right_summit_imu_imu_plugin"><topicName>imu/data</topicName><bodyName>right_summit_imu_link</bodyName><updateRateHZ>100.0</updateRateHZ><gaussianNoise>0.0</gaussianNoise><xyzOffset>0 0 0</xyzOffset><rpyOffset>0 0 0</rpyOffset><frameName>right_summit_imu_link</frameName></plugin><pose>0 0 0 0 0 0</pose></sensor></gazebo><joint name="right_summit_front_laser_base_joint" type="fixed"><origin rpy="0 -3.141592653589793 2.356194490192345" xyz="0.2865 -0.20894 0.2973"/><parent link="right_summit_base_link"/><child link="right_summit_front_laser_base_link"/><limit effort="100" lower="0.0" upper="0.0" velocity="100"/></joint><link name="right_summit_front_laser_base_link"><collision><origin rpy="0 0 0" xyz="0 0 0"/><geometry><!--<box size="0.106 0.094 0.152"/>--><!--<cylinder radius="0.058" length="0.152"/>--><mesh filename="package://robotnik_sensors/meshes/sick_s300.dae"/></geometry></collision><visual><origin rpy="-1.5707963267948966 0 0" xyz="0 0 0"/><geometry><mesh filename="package://robotnik_sensors/meshes/sick_s300_color.dae"/></geometry></visual><inertial><mass value="1.2"/><origin rpy="0 0 0" xyz="0 0.0 0.0751"/><inertia ixx="0.0034339999999999996" ixy="0" ixz="0" iyy="0.0033507999999999993" iyz="0" izz="0.0021639999999999997"/></inertial></link><joint name="right_summit_front_laser_joint" type="fixed"><parent link="right_summit_front_laser_base_link"/><child link="right_summit_front_laser_link"/><origin rpy="0 0 0" xyz="0.0 0 0.116"/></joint><link name="right_summit_front_laser_link"/><gazebo reference="right_summit_front_laser_link"><sensor name="right_summit_front_laser_sensor" type="ray"><pose>0 0 0 0 0 0</pose><visualize>false</visualize><update_rate>12.5</update_rate><ray><scan><horizontal><samples>541</samples><resolution>1</resolution><min_angle>-2.3562</min_angle><max_angle>2.3562</max_angle></horizontal></scan><range><min>0.10</min><max>30.0</max><resolution>0.03</resolution></range><noise><type>gaussian</type><mean>0.0</mean><stddev>0.03</stddev></noise></ray><plugin filename="libgazebo_ros_ray_sensor.so" name="right_summit_front_laser_controller"><ros><remapping>~/out:=front_laser/scan</remapping></ros><!-- when leaving away frame_name it defaults to base_footprint instead--><frame_name>right_summit_front_laser_link</frame_name><output_type>sensor_msgs/LaserScan</output_type></plugin></sensor></gazebo><joint name="right_summit_rear_laser_base_joint" type="fixed"><origin rpy="0 -3.141592653589793 -0.7853981633974483" xyz="-0.2865 0.20894 0.2973"/><parent link="right_summit_base_link"/><child link="right_summit_rear_laser_base_link"/><limit effort="100" lower="0.0" upper="0.0" velocity="100"/></joint><link name="right_summit_rear_laser_base_link"><collision><origin rpy="0 0 0" xyz="0 0 0"/><geometry><!--<box size="0.106 0.094 0.152"/>--><!--<cylinder radius="0.058" length="0.152"/>--><mesh filename="package://robotnik_sensors/meshes/sick_s300.dae"/></geometry></collision><visual><origin rpy="-1.5707963267948966 0 0" xyz="0 0 0"/><geometry><mesh filename="package://robotnik_sensors/meshes/sick_s300_color.dae"/></geometry></visual><inertial><mass value="1.2"/><origin rpy="0 0 0" xyz="0 0.0 0.0751"/><inertia ixx="0.0034339999999999996" ixy="0" ixz="0" iyy="0.0033507999999999993" iyz="0" izz="0.0021639999999999997"/></inertial></link><joint name="right_summit_rear_laser_joint" type="fixed"><parent link="right_summit_rear_laser_base_link"/><child link="right_summit_rear_laser_link"/><origin rpy="0 0 0" xyz="0.0 0 0.116"/></joint><link name="right_summit_rear_laser_link"/><gazebo reference="right_summit_rear_laser_link"><sensor name="right_summit_rear_laser_sensor" type="ray"><pose>0 0 0 0 0 0</pose><visualize>false</visualize><update_rate>12.5</update_rate><ray><scan><horizontal><samples>541</samples><resolution>1</resolution><min_angle>-2.3562</min_angle><max_angle>2.3562</max_angle></horizontal></scan><range><min>0.10</min><max>30.0</max><resolution>0.03</resolution></range><noise><type>gaussian</type><mean>0.0</mean><stddev>0.03</stddev></noise></ray><plugin filename="libgazebo_ros_ray_sensor.so" name="right_summit_rear_laser_controller"><ros><remapping>~/out:=rear_laser/scan</remapping></ros><!-- when leaving away frame_name it defaults to base_footprint instead--><frame_name>right_summit_rear_laser_link</frame_name><output_type>sensor_msgs/LaserScan</output_type></plugin></sensor></gazebo><!--xacro:sensor_axis_m5013 prefix="$(arg prefix)front_ptz_camera" parent="$(arg prefix)base_link">
			<origin xyz="${front_ptz_camera_offset_x} ${front_ptz_camera_offset_y} ${front_ptz_camera_offset_z}" rpy="${-PI/2} 0 0"/>
		</xacro:sensor_axis_m5013--><!--xacro:sensor_axis_m5013 prefix="$(arg prefix)rear_ptz_camera" parent="$(arg prefix)base_link">
			<origin xyz="${rear_ptz_camera_offset_x} ${rear_ptz_camera_offset_y} ${rear_ptz_camera_offset_z}" rpy="${-PI/2} 0 ${PI}"/>
		</xacro:sensor_axis_m5013--><!-- <xacro:sensor_orbbec_astra prefix="$(arg prefix)front_rgbd_camera" parent="$(arg prefix)base_link" prefix_topic="front_rgbd_camera">
			<origin xyz="${front_rgbd_camera_offset_x} ${front_rgbd_camera_offset_y} ${front_rgbd_camera_offset_z}" rpy="0 0 0"/>
		</xacro:sensor_orbbec_astra> --><!--xacro:sensor_gps prefix="$(arg prefix)gps" parent="$(arg prefix)base_link">
			<origin xyz="${gps_offset_x} ${gps_offset_y} ${gps_offset_z}" rpy="0 0 0"/>
		</xacro:sensor_gps--><!-- <xacro:summit_xl prefix="${prefix)}" publish_bf="true" hq="true"/> --><!-- 
    <joint name="$(arg namespace)_world_prismatic_1_joint" type="prismatic">
        <origin xyz="$(arg xyz_base)" rpy="0 0 0" /> 
        <parent link="$(arg parent_base)"/>
        <child link="$(arg namespace)_prismatic_1" />
        <limit lower="0" upper="2"
             effort="10" velocity="10"/>
    </joint> 

    <joint name="$(arg namespace)_prismatic_1_prismatic_2_joint" type="prismatic">
        <origin xyz="0 0 0" rpy="0 0 0" /> 
        <parent link="$(arg namespace)_prismatic_1"/>
        <child link="$(arg namespace)_prismatic_2" />
        <limit lower="0" upper="2"
             effort="10" velocity="10"/>
    </joint> 

    <joint name="$(arg namespace)_prismatic_2_revolute" type="revolute">
        <origin xyz="0 0 0" rpy="0 0 0" /> 
        <parent link="$(arg namespace)_prismatic_2"/>
        <child link="$(arg namespace)_revolute" />
        <limit lower="0" upper="2"
             effort="10" velocity="10"/>
    </joint> 

    <joint name="$(arg namespace)_revolute_base_joint" type="fixed">
        <origin xyz="0 0 0" rpy="0 0 0" /> 
        <parent link="$(arg namespace)_prismatic_2"/>
        <child link="$(arg namespace)_summit_base_footprint" />
        <limit lower="0" upper="2"
             effort="10" velocity="10"/>
    </joint>  --></robot><!-- <joint name="$(arg namespace)_world_prismatic_1_joint" type="prismatic">
        <origin xyz="$(arg xyz_base)" rpy="0 0 0" /> 
        <parent link="$(arg parent_base)"/>
        <child link="$(arg namespace)_prismatic_1" />
        <limit lower="0" upper="2"
             effort="10" velocity="10"/>
    </joint> 

    <joint name="$(arg namespace)_prismatic_1_prismatic_2_joint" type="prismatic">
        <origin xyz="0 0 0" rpy="0 0 0" /> 
        <parent link="$(arg namespace)_prismatic_1"/>
        <child link="$(arg namespace)_prismatic_2" />
        <limit lower="0" upper="2"
             effort="10" velocity="10"/>
    </joint> 

    <joint name="$(arg namespace)_prismatic_2_revolute_joint" type="revolute">
        <origin xyz="0 0 0" rpy="0 0 0" /> 
        <parent link="$(arg namespace)_prismatic_2"/>
        <child link="$(arg namespace)_revolute" />
        <limit lower="0" upper="2"
             effort="10" velocity="10"/>
    </joint> 

    <joint name="$(arg namespace)_revolute_base_footprint_joint" type="fixed">
        <origin xyz="0 0 0" rpy="0 0 0" /> 
        <parent link="$(arg namespace)_revolute"/>
        <child link="$(arg namespace)_summit_base_footprint" /> -->